2014-10-22 08:29:28,405 pool _finalize_fairy 574 : Exception during reset or similar
Traceback (most recent call last):
  File "/Library/Python/2.7/site-packages/SQLAlchemy-0.9.8-py2.7-macosx-10.10-intel.egg/sqlalchemy/pool.py", line 567, in _finalize_fairy
    fairy._reset(pool)
  File "/Library/Python/2.7/site-packages/SQLAlchemy-0.9.8-py2.7-macosx-10.10-intel.egg/sqlalchemy/pool.py", line 701, in _reset
    pool._dialect.do_rollback(self)
  File "/Library/Python/2.7/site-packages/SQLAlchemy-0.9.8-py2.7-macosx-10.10-intel.egg/sqlalchemy/engine/default.py", line 406, in do_rollback
    dbapi_connection.rollback()
ProgrammingError: SQLite objects created in a thread can only be used in that same thread.The object was created in thread id 4359983104 and this is thread id 140735223169792
2014-10-22 08:29:28,407 pool _close_connection 255 : Exception closing connection <sqlite3.Connection object at 0x102c7c200>
Traceback (most recent call last):
  File "/Library/Python/2.7/site-packages/SQLAlchemy-0.9.8-py2.7-macosx-10.10-intel.egg/sqlalchemy/pool.py", line 250, in _close_connection
    self._dialect.do_close(connection)
  File "/Library/Python/2.7/site-packages/SQLAlchemy-0.9.8-py2.7-macosx-10.10-intel.egg/sqlalchemy/engine/default.py", line 412, in do_close
    dbapi_connection.close()
ProgrammingError: SQLite objects created in a thread can only be used in that same thread.The object was created in thread id 4359983104 and this is thread id 140735223169792
2014-10-22 08:31:19,808 pool _finalize_fairy 574 : Exception during reset or similar
Traceback (most recent call last):
  File "/Library/Python/2.7/site-packages/SQLAlchemy-0.9.8-py2.7-macosx-10.10-intel.egg/sqlalchemy/pool.py", line 567, in _finalize_fairy
    fairy._reset(pool)
  File "/Library/Python/2.7/site-packages/SQLAlchemy-0.9.8-py2.7-macosx-10.10-intel.egg/sqlalchemy/pool.py", line 701, in _reset
    pool._dialect.do_rollback(self)
  File "/Library/Python/2.7/site-packages/SQLAlchemy-0.9.8-py2.7-macosx-10.10-intel.egg/sqlalchemy/engine/default.py", line 406, in do_rollback
    dbapi_connection.rollback()
ProgrammingError: SQLite objects created in a thread can only be used in that same thread.The object was created in thread id 4534046720 and this is thread id 140735223169792
2014-10-22 08:31:19,808 pool _close_connection 255 : Exception closing connection <sqlite3.Connection object at 0x10d173770>
Traceback (most recent call last):
  File "/Library/Python/2.7/site-packages/SQLAlchemy-0.9.8-py2.7-macosx-10.10-intel.egg/sqlalchemy/pool.py", line 250, in _close_connection
    self._dialect.do_close(connection)
  File "/Library/Python/2.7/site-packages/SQLAlchemy-0.9.8-py2.7-macosx-10.10-intel.egg/sqlalchemy/engine/default.py", line 412, in do_close
    dbapi_connection.close()
ProgrammingError: SQLite objects created in a thread can only be used in that same thread.The object was created in thread id 4534046720 and this is thread id 140735223169792
2014-10-22 09:49:05,190 pool _finalize_fairy 574 : Exception during reset or similar
Traceback (most recent call last):
  File "/Library/Python/2.7/site-packages/SQLAlchemy-0.9.8-py2.7-macosx-10.10-intel.egg/sqlalchemy/pool.py", line 567, in _finalize_fairy
    fairy._reset(pool)
  File "/Library/Python/2.7/site-packages/SQLAlchemy-0.9.8-py2.7-macosx-10.10-intel.egg/sqlalchemy/pool.py", line 701, in _reset
    pool._dialect.do_rollback(self)
  File "/Library/Python/2.7/site-packages/SQLAlchemy-0.9.8-py2.7-macosx-10.10-intel.egg/sqlalchemy/engine/default.py", line 406, in do_rollback
    dbapi_connection.rollback()
ProgrammingError: SQLite objects created in a thread can only be used in that same thread.The object was created in thread id 4349497344 and this is thread id 140735223169792
2014-10-22 09:49:05,194 pool _close_connection 255 : Exception closing connection <sqlite3.Connection object at 0x1021a7770>
Traceback (most recent call last):
  File "/Library/Python/2.7/site-packages/SQLAlchemy-0.9.8-py2.7-macosx-10.10-intel.egg/sqlalchemy/pool.py", line 250, in _close_connection
    self._dialect.do_close(connection)
  File "/Library/Python/2.7/site-packages/SQLAlchemy-0.9.8-py2.7-macosx-10.10-intel.egg/sqlalchemy/engine/default.py", line 412, in do_close
    dbapi_connection.close()
ProgrammingError: SQLite objects created in a thread can only be used in that same thread.The object was created in thread id 4349497344 and this is thread id 140735223169792
2014-10-22 12:08:54,555 pool _finalize_fairy 574 : Exception during reset or similar
Traceback (most recent call last):
  File "/Library/Python/2.7/site-packages/SQLAlchemy-0.9.8-py2.7-macosx-10.10-intel.egg/sqlalchemy/pool.py", line 567, in _finalize_fairy
    fairy._reset(pool)
  File "/Library/Python/2.7/site-packages/SQLAlchemy-0.9.8-py2.7-macosx-10.10-intel.egg/sqlalchemy/pool.py", line 701, in _reset
    pool._dialect.do_rollback(self)
  File "/Library/Python/2.7/site-packages/SQLAlchemy-0.9.8-py2.7-macosx-10.10-intel.egg/sqlalchemy/engine/default.py", line 406, in do_rollback
    dbapi_connection.rollback()
ProgrammingError: SQLite objects created in a thread can only be used in that same thread.The object was created in thread id 4571795456 and this is thread id 140735197999872
2014-10-22 12:08:54,561 pool _close_connection 255 : Exception closing connection <sqlite3.Connection object at 0x10f58f770>
Traceback (most recent call last):
  File "/Library/Python/2.7/site-packages/SQLAlchemy-0.9.8-py2.7-macosx-10.10-intel.egg/sqlalchemy/pool.py", line 250, in _close_connection
    self._dialect.do_close(connection)
  File "/Library/Python/2.7/site-packages/SQLAlchemy-0.9.8-py2.7-macosx-10.10-intel.egg/sqlalchemy/engine/default.py", line 412, in do_close
    dbapi_connection.close()
ProgrammingError: SQLite objects created in a thread can only be used in that same thread.The object was created in thread id 4571795456 and this is thread id 140735197999872
2014-10-22 12:10:50,646 pool _finalize_fairy 574 : Exception during reset or similar
Traceback (most recent call last):
  File "/Library/Python/2.7/site-packages/SQLAlchemy-0.9.8-py2.7-macosx-10.10-intel.egg/sqlalchemy/pool.py", line 567, in _finalize_fairy
    fairy._reset(pool)
  File "/Library/Python/2.7/site-packages/SQLAlchemy-0.9.8-py2.7-macosx-10.10-intel.egg/sqlalchemy/pool.py", line 701, in _reset
    pool._dialect.do_rollback(self)
  File "/Library/Python/2.7/site-packages/SQLAlchemy-0.9.8-py2.7-macosx-10.10-intel.egg/sqlalchemy/engine/default.py", line 406, in do_rollback
    dbapi_connection.rollback()
ProgrammingError: SQLite objects created in a thread can only be used in that same thread.The object was created in thread id 4527755264 and this is thread id 140735197999872
2014-10-22 12:10:50,648 pool _close_connection 255 : Exception closing connection <sqlite3.Connection object at 0x10cce3770>
Traceback (most recent call last):
  File "/Library/Python/2.7/site-packages/SQLAlchemy-0.9.8-py2.7-macosx-10.10-intel.egg/sqlalchemy/pool.py", line 250, in _close_connection
    self._dialect.do_close(connection)
  File "/Library/Python/2.7/site-packages/SQLAlchemy-0.9.8-py2.7-macosx-10.10-intel.egg/sqlalchemy/engine/default.py", line 412, in do_close
    dbapi_connection.close()
ProgrammingError: SQLite objects created in a thread can only be used in that same thread.The object was created in thread id 4527755264 and this is thread id 140735197999872
2014-10-22 21:11:03,154 pool _finalize_fairy 574 : Exception during reset or similar
Traceback (most recent call last):
  File "/Library/Python/2.7/site-packages/SQLAlchemy-0.9.8-py2.7-macosx-10.10-intel.egg/sqlalchemy/pool.py", line 567, in _finalize_fairy
    fairy._reset(pool)
  File "/Library/Python/2.7/site-packages/SQLAlchemy-0.9.8-py2.7-macosx-10.10-intel.egg/sqlalchemy/pool.py", line 701, in _reset
    pool._dialect.do_rollback(self)
  File "/Library/Python/2.7/site-packages/SQLAlchemy-0.9.8-py2.7-macosx-10.10-intel.egg/sqlalchemy/engine/default.py", line 406, in do_rollback
    dbapi_connection.rollback()
ProgrammingError: SQLite objects created in a thread can only be used in that same thread.The object was created in thread id 4580184064 and this is thread id 140735197999872
2014-10-22 21:11:03,157 pool _close_connection 255 : Exception closing connection <sqlite3.Connection object at 0x10fe31770>
Traceback (most recent call last):
  File "/Library/Python/2.7/site-packages/SQLAlchemy-0.9.8-py2.7-macosx-10.10-intel.egg/sqlalchemy/pool.py", line 250, in _close_connection
    self._dialect.do_close(connection)
  File "/Library/Python/2.7/site-packages/SQLAlchemy-0.9.8-py2.7-macosx-10.10-intel.egg/sqlalchemy/engine/default.py", line 412, in do_close
    dbapi_connection.close()
ProgrammingError: SQLite objects created in a thread can only be used in that same thread.The object was created in thread id 4580184064 and this is thread id 140735197999872
2014-10-23 09:44:38,828 pool _finalize_fairy 574 : Exception during reset or similar
Traceback (most recent call last):
  File "/Library/Python/2.7/site-packages/SQLAlchemy-0.9.8-py2.7-macosx-10.10-intel.egg/sqlalchemy/pool.py", line 567, in _finalize_fairy
    fairy._reset(pool)
  File "/Library/Python/2.7/site-packages/SQLAlchemy-0.9.8-py2.7-macosx-10.10-intel.egg/sqlalchemy/pool.py", line 701, in _reset
    pool._dialect.do_rollback(self)
  File "/Library/Python/2.7/site-packages/SQLAlchemy-0.9.8-py2.7-macosx-10.10-intel.egg/sqlalchemy/engine/default.py", line 406, in do_rollback
    dbapi_connection.rollback()
ProgrammingError: SQLite objects created in a thread can only be used in that same thread.The object was created in thread id 4347400192 and this is thread id 140735197999872
2014-10-23 09:44:38,833 pool _close_connection 255 : Exception closing connection <sqlite3.Connection object at 0x10204a770>
Traceback (most recent call last):
  File "/Library/Python/2.7/site-packages/SQLAlchemy-0.9.8-py2.7-macosx-10.10-intel.egg/sqlalchemy/pool.py", line 250, in _close_connection
    self._dialect.do_close(connection)
  File "/Library/Python/2.7/site-packages/SQLAlchemy-0.9.8-py2.7-macosx-10.10-intel.egg/sqlalchemy/engine/default.py", line 412, in do_close
    dbapi_connection.close()
ProgrammingError: SQLite objects created in a thread can only be used in that same thread.The object was created in thread id 4347400192 and this is thread id 140735197999872
2014-10-24 08:46:40,615 pool _finalize_fairy 574 : Exception during reset or similar
Traceback (most recent call last):
  File "/Library/Python/2.7/site-packages/SQLAlchemy-0.9.8-py2.7-macosx-10.10-intel.egg/sqlalchemy/pool.py", line 567, in _finalize_fairy
    fairy._reset(pool)
  File "/Library/Python/2.7/site-packages/SQLAlchemy-0.9.8-py2.7-macosx-10.10-intel.egg/sqlalchemy/pool.py", line 701, in _reset
    pool._dialect.do_rollback(self)
  File "/Library/Python/2.7/site-packages/SQLAlchemy-0.9.8-py2.7-macosx-10.10-intel.egg/sqlalchemy/engine/default.py", line 406, in do_rollback
    dbapi_connection.rollback()
ProgrammingError: SQLite objects created in a thread can only be used in that same thread.The object was created in thread id 4479651840 and this is thread id 140735197999872
2014-10-24 08:46:40,618 pool _close_connection 255 : Exception closing connection <sqlite3.Connection object at 0x109da1770>
Traceback (most recent call last):
  File "/Library/Python/2.7/site-packages/SQLAlchemy-0.9.8-py2.7-macosx-10.10-intel.egg/sqlalchemy/pool.py", line 250, in _close_connection
    self._dialect.do_close(connection)
  File "/Library/Python/2.7/site-packages/SQLAlchemy-0.9.8-py2.7-macosx-10.10-intel.egg/sqlalchemy/engine/default.py", line 412, in do_close
    dbapi_connection.close()
ProgrammingError: SQLite objects created in a thread can only be used in that same thread.The object was created in thread id 4479651840 and this is thread id 140735197999872
2014-10-24 16:22:05,848 pool _finalize_fairy 574 : Exception during reset or similar
Traceback (most recent call last):
  File "/Library/Python/2.7/site-packages/SQLAlchemy-0.9.8-py2.7-macosx-10.10-intel.egg/sqlalchemy/pool.py", line 567, in _finalize_fairy
    fairy._reset(pool)
  File "/Library/Python/2.7/site-packages/SQLAlchemy-0.9.8-py2.7-macosx-10.10-intel.egg/sqlalchemy/pool.py", line 701, in _reset
    pool._dialect.do_rollback(self)
  File "/Library/Python/2.7/site-packages/SQLAlchemy-0.9.8-py2.7-macosx-10.10-intel.egg/sqlalchemy/engine/default.py", line 406, in do_rollback
    dbapi_connection.rollback()
ProgrammingError: SQLite objects created in a thread can only be used in that same thread.The object was created in thread id 4592898048 and this is thread id 140735284482816
2014-10-24 16:22:05,853 pool _close_connection 255 : Exception closing connection <sqlite3.Connection object at 0x110b3e940>
Traceback (most recent call last):
  File "/Library/Python/2.7/site-packages/SQLAlchemy-0.9.8-py2.7-macosx-10.10-intel.egg/sqlalchemy/pool.py", line 250, in _close_connection
    self._dialect.do_close(connection)
  File "/Library/Python/2.7/site-packages/SQLAlchemy-0.9.8-py2.7-macosx-10.10-intel.egg/sqlalchemy/engine/default.py", line 412, in do_close
    dbapi_connection.close()
ProgrammingError: SQLite objects created in a thread can only be used in that same thread.The object was created in thread id 4592898048 and this is thread id 140735284482816
2014-10-27 12:59:42,046 pool _finalize_fairy 574 : Exception during reset or similar
Traceback (most recent call last):
  File "/Library/Python/2.7/site-packages/SQLAlchemy-0.9.8-py2.7-macosx-10.10-intel.egg/sqlalchemy/pool.py", line 567, in _finalize_fairy
    fairy._reset(pool)
  File "/Library/Python/2.7/site-packages/SQLAlchemy-0.9.8-py2.7-macosx-10.10-intel.egg/sqlalchemy/pool.py", line 701, in _reset
    pool._dialect.do_rollback(self)
  File "/Library/Python/2.7/site-packages/SQLAlchemy-0.9.8-py2.7-macosx-10.10-intel.egg/sqlalchemy/engine/default.py", line 406, in do_rollback
    dbapi_connection.rollback()
ProgrammingError: SQLite objects created in a thread can only be used in that same thread.The object was created in thread id 4461182976 and this is thread id 140735284482816
2014-10-27 12:59:42,050 pool _close_connection 255 : Exception closing connection <sqlite3.Connection object at 0x108bf5858>
Traceback (most recent call last):
  File "/Library/Python/2.7/site-packages/SQLAlchemy-0.9.8-py2.7-macosx-10.10-intel.egg/sqlalchemy/pool.py", line 250, in _close_connection
    self._dialect.do_close(connection)
  File "/Library/Python/2.7/site-packages/SQLAlchemy-0.9.8-py2.7-macosx-10.10-intel.egg/sqlalchemy/engine/default.py", line 412, in do_close
    dbapi_connection.close()
ProgrammingError: SQLite objects created in a thread can only be used in that same thread.The object was created in thread id 4461182976 and this is thread id 140735284482816
2014-10-29 12:55:38,872 pool _finalize_fairy 574 : Exception during reset or similar
Traceback (most recent call last):
  File "/Library/Python/2.7/site-packages/SQLAlchemy-0.9.8-py2.7-macosx-10.10-intel.egg/sqlalchemy/pool.py", line 567, in _finalize_fairy
    fairy._reset(pool)
  File "/Library/Python/2.7/site-packages/SQLAlchemy-0.9.8-py2.7-macosx-10.10-intel.egg/sqlalchemy/pool.py", line 701, in _reset
    pool._dialect.do_rollback(self)
  File "/Library/Python/2.7/site-packages/SQLAlchemy-0.9.8-py2.7-macosx-10.10-intel.egg/sqlalchemy/engine/default.py", line 406, in do_rollback
    dbapi_connection.rollback()
ProgrammingError: SQLite objects created in a thread can only be used in that same thread.The object was created in thread id 4582281216 and this is thread id 140735284482816
2014-10-29 12:55:38,878 pool _close_connection 255 : Exception closing connection <sqlite3.Connection object at 0x11009c770>
Traceback (most recent call last):
  File "/Library/Python/2.7/site-packages/SQLAlchemy-0.9.8-py2.7-macosx-10.10-intel.egg/sqlalchemy/pool.py", line 250, in _close_connection
    self._dialect.do_close(connection)
  File "/Library/Python/2.7/site-packages/SQLAlchemy-0.9.8-py2.7-macosx-10.10-intel.egg/sqlalchemy/engine/default.py", line 412, in do_close
    dbapi_connection.close()
ProgrammingError: SQLite objects created in a thread can only be used in that same thread.The object was created in thread id 4582281216 and this is thread id 140735284482816
2014-10-29 17:59:50,719 pool _finalize_fairy 574 : Exception during reset or similar
Traceback (most recent call last):
  File "/Library/Python/2.7/site-packages/SQLAlchemy-0.9.8-py2.7-macosx-10.10-intel.egg/sqlalchemy/pool.py", line 567, in _finalize_fairy
    fairy._reset(pool)
  File "/Library/Python/2.7/site-packages/SQLAlchemy-0.9.8-py2.7-macosx-10.10-intel.egg/sqlalchemy/pool.py", line 701, in _reset
    pool._dialect.do_rollback(self)
  File "/Library/Python/2.7/site-packages/SQLAlchemy-0.9.8-py2.7-macosx-10.10-intel.egg/sqlalchemy/engine/default.py", line 406, in do_rollback
    dbapi_connection.rollback()
ProgrammingError: SQLite objects created in a thread can only be used in that same thread.The object was created in thread id 4578086912 and this is thread id 140735284482816
2014-10-29 17:59:50,724 pool _close_connection 255 : Exception closing connection <sqlite3.Connection object at 0x10fb4c770>
Traceback (most recent call last):
  File "/Library/Python/2.7/site-packages/SQLAlchemy-0.9.8-py2.7-macosx-10.10-intel.egg/sqlalchemy/pool.py", line 250, in _close_connection
    self._dialect.do_close(connection)
  File "/Library/Python/2.7/site-packages/SQLAlchemy-0.9.8-py2.7-macosx-10.10-intel.egg/sqlalchemy/engine/default.py", line 412, in do_close
    dbapi_connection.close()
ProgrammingError: SQLite objects created in a thread can only be used in that same thread.The object was created in thread id 4578086912 and this is thread id 140735284482816
2014-10-30 09:47:53,014 pool _finalize_fairy 574 : Exception during reset or similar
Traceback (most recent call last):
  File "/Library/Python/2.7/site-packages/SQLAlchemy-0.9.8-py2.7-macosx-10.10-intel.egg/sqlalchemy/pool.py", line 567, in _finalize_fairy
    fairy._reset(pool)
  File "/Library/Python/2.7/site-packages/SQLAlchemy-0.9.8-py2.7-macosx-10.10-intel.egg/sqlalchemy/pool.py", line 701, in _reset
    pool._dialect.do_rollback(self)
  File "/Library/Python/2.7/site-packages/SQLAlchemy-0.9.8-py2.7-macosx-10.10-intel.egg/sqlalchemy/engine/default.py", line 406, in do_rollback
    dbapi_connection.rollback()
ProgrammingError: SQLite objects created in a thread can only be used in that same thread.The object was created in thread id 4565504000 and this is thread id 140735284482816
2014-10-30 09:47:53,018 pool _close_connection 255 : Exception closing connection <sqlite3.Connection object at 0x10efc1770>
Traceback (most recent call last):
  File "/Library/Python/2.7/site-packages/SQLAlchemy-0.9.8-py2.7-macosx-10.10-intel.egg/sqlalchemy/pool.py", line 250, in _close_connection
    self._dialect.do_close(connection)
  File "/Library/Python/2.7/site-packages/SQLAlchemy-0.9.8-py2.7-macosx-10.10-intel.egg/sqlalchemy/engine/default.py", line 412, in do_close
    dbapi_connection.close()
ProgrammingError: SQLite objects created in a thread can only be used in that same thread.The object was created in thread id 4565504000 and this is thread id 140735284482816
2014-10-31 14:55:01,520 pool _finalize_fairy 574 : Exception during reset or similar
Traceback (most recent call last):
  File "/Library/Python/2.7/site-packages/SQLAlchemy-0.9.8-py2.7-macosx-10.10-intel.egg/sqlalchemy/pool.py", line 567, in _finalize_fairy
    fairy._reset(pool)
  File "/Library/Python/2.7/site-packages/SQLAlchemy-0.9.8-py2.7-macosx-10.10-intel.egg/sqlalchemy/pool.py", line 701, in _reset
    pool._dialect.do_rollback(self)
  File "/Library/Python/2.7/site-packages/SQLAlchemy-0.9.8-py2.7-macosx-10.10-intel.egg/sqlalchemy/engine/default.py", line 406, in do_rollback
    dbapi_connection.rollback()
ProgrammingError: SQLite objects created in a thread can only be used in that same thread.The object was created in thread id 4401926144 and this is thread id 140735306928896
2014-10-31 14:55:01,524 pool _close_connection 255 : Exception closing connection <sqlite3.Connection object at 0x105405770>
Traceback (most recent call last):
  File "/Library/Python/2.7/site-packages/SQLAlchemy-0.9.8-py2.7-macosx-10.10-intel.egg/sqlalchemy/pool.py", line 250, in _close_connection
    self._dialect.do_close(connection)
  File "/Library/Python/2.7/site-packages/SQLAlchemy-0.9.8-py2.7-macosx-10.10-intel.egg/sqlalchemy/engine/default.py", line 412, in do_close
    dbapi_connection.close()
ProgrammingError: SQLite objects created in a thread can only be used in that same thread.The object was created in thread id 4401926144 and this is thread id 140735306928896
2014-11-04 10:40:13,339 pool _finalize_fairy 574 : Exception during reset or similar
Traceback (most recent call last):
  File "/Library/Python/2.7/site-packages/SQLAlchemy-0.9.8-py2.7-macosx-10.10-intel.egg/sqlalchemy/pool.py", line 567, in _finalize_fairy
    fairy._reset(pool)
  File "/Library/Python/2.7/site-packages/SQLAlchemy-0.9.8-py2.7-macosx-10.10-intel.egg/sqlalchemy/pool.py", line 701, in _reset
    pool._dialect.do_rollback(self)
  File "/Library/Python/2.7/site-packages/SQLAlchemy-0.9.8-py2.7-macosx-10.10-intel.egg/sqlalchemy/engine/default.py", line 406, in do_rollback
    dbapi_connection.rollback()
ProgrammingError: SQLite objects created in a thread can only be used in that same thread.The object was created in thread id 4385148928 and this is thread id 140735306928896
2014-11-04 10:40:13,343 pool _close_connection 255 : Exception closing connection <sqlite3.Connection object at 0x104371770>
Traceback (most recent call last):
  File "/Library/Python/2.7/site-packages/SQLAlchemy-0.9.8-py2.7-macosx-10.10-intel.egg/sqlalchemy/pool.py", line 250, in _close_connection
    self._dialect.do_close(connection)
  File "/Library/Python/2.7/site-packages/SQLAlchemy-0.9.8-py2.7-macosx-10.10-intel.egg/sqlalchemy/engine/default.py", line 412, in do_close
    dbapi_connection.close()
ProgrammingError: SQLite objects created in a thread can only be used in that same thread.The object was created in thread id 4385148928 and this is thread id 140735306928896
2014-11-04 14:03:31,416 pool _finalize_fairy 574 : Exception during reset or similar
Traceback (most recent call last):
  File "/Library/Python/2.7/site-packages/SQLAlchemy-0.9.8-py2.7-macosx-10.10-intel.egg/sqlalchemy/pool.py", line 567, in _finalize_fairy
    fairy._reset(pool)
  File "/Library/Python/2.7/site-packages/SQLAlchemy-0.9.8-py2.7-macosx-10.10-intel.egg/sqlalchemy/pool.py", line 701, in _reset
    pool._dialect.do_rollback(self)
  File "/Library/Python/2.7/site-packages/SQLAlchemy-0.9.8-py2.7-macosx-10.10-intel.egg/sqlalchemy/engine/default.py", line 406, in do_rollback
    dbapi_connection.rollback()
ProgrammingError: SQLite objects created in a thread can only be used in that same thread.The object was created in thread id 4442845184 and this is thread id 140735306928896
2014-11-04 14:03:31,419 pool _close_connection 255 : Exception closing connection <sqlite3.Connection object at 0x107acb770>
Traceback (most recent call last):
  File "/Library/Python/2.7/site-packages/SQLAlchemy-0.9.8-py2.7-macosx-10.10-intel.egg/sqlalchemy/pool.py", line 250, in _close_connection
    self._dialect.do_close(connection)
  File "/Library/Python/2.7/site-packages/SQLAlchemy-0.9.8-py2.7-macosx-10.10-intel.egg/sqlalchemy/engine/default.py", line 412, in do_close
    dbapi_connection.close()
ProgrammingError: SQLite objects created in a thread can only be used in that same thread.The object was created in thread id 4442845184 and this is thread id 140735306928896
2014-11-05 13:26:20,870 pool _finalize_fairy 574 : Exception during reset or similar
Traceback (most recent call last):
  File "/Library/Python/2.7/site-packages/SQLAlchemy-0.9.8-py2.7-macosx-10.10-intel.egg/sqlalchemy/pool.py", line 567, in _finalize_fairy
    fairy._reset(pool)
  File "/Library/Python/2.7/site-packages/SQLAlchemy-0.9.8-py2.7-macosx-10.10-intel.egg/sqlalchemy/pool.py", line 701, in _reset
    pool._dialect.do_rollback(self)
  File "/Library/Python/2.7/site-packages/SQLAlchemy-0.9.8-py2.7-macosx-10.10-intel.egg/sqlalchemy/engine/default.py", line 406, in do_rollback
    dbapi_connection.rollback()
ProgrammingError: SQLite objects created in a thread can only be used in that same thread.The object was created in thread id 4330622976 and this is thread id 140735306928896
2014-11-05 13:26:20,876 pool _close_connection 255 : Exception closing connection <sqlite3.Connection object at 0x10110b770>
Traceback (most recent call last):
  File "/Library/Python/2.7/site-packages/SQLAlchemy-0.9.8-py2.7-macosx-10.10-intel.egg/sqlalchemy/pool.py", line 250, in _close_connection
    self._dialect.do_close(connection)
  File "/Library/Python/2.7/site-packages/SQLAlchemy-0.9.8-py2.7-macosx-10.10-intel.egg/sqlalchemy/engine/default.py", line 412, in do_close
    dbapi_connection.close()
ProgrammingError: SQLite objects created in a thread can only be used in that same thread.The object was created in thread id 4330622976 and this is thread id 140735306928896
2014-11-05 17:42:17,127 geeknote main 907 : App error: [Errno 8] nodename nor servname provided, or not known
2014-11-05 17:42:32,766 geeknote main 907 : App error: [Errno 8] nodename nor servname provided, or not known
2014-11-10 08:38:18,357 pool _finalize_fairy 574 : Exception during reset or similar
Traceback (most recent call last):
  File "/Library/Python/2.7/site-packages/SQLAlchemy-0.9.8-py2.7-macosx-10.10-intel.egg/sqlalchemy/pool.py", line 567, in _finalize_fairy
    fairy._reset(pool)
  File "/Library/Python/2.7/site-packages/SQLAlchemy-0.9.8-py2.7-macosx-10.10-intel.egg/sqlalchemy/pool.py", line 701, in _reset
    pool._dialect.do_rollback(self)
  File "/Library/Python/2.7/site-packages/SQLAlchemy-0.9.8-py2.7-macosx-10.10-intel.egg/sqlalchemy/engine/default.py", line 406, in do_rollback
    dbapi_connection.rollback()
ProgrammingError: SQLite objects created in a thread can only be used in that same thread.The object was created in thread id 4450697216 and this is thread id 140735306928896
2014-11-10 08:38:18,360 pool _close_connection 255 : Exception closing connection <sqlite3.Connection object at 0x1081c0770>
Traceback (most recent call last):
  File "/Library/Python/2.7/site-packages/SQLAlchemy-0.9.8-py2.7-macosx-10.10-intel.egg/sqlalchemy/pool.py", line 250, in _close_connection
    self._dialect.do_close(connection)
  File "/Library/Python/2.7/site-packages/SQLAlchemy-0.9.8-py2.7-macosx-10.10-intel.egg/sqlalchemy/engine/default.py", line 412, in do_close
    dbapi_connection.close()
ProgrammingError: SQLite objects created in a thread can only be used in that same thread.The object was created in thread id 4450697216 and this is thread id 140735306928896
2014-11-10 14:48:56,848 pool _finalize_fairy 574 : Exception during reset or similar
Traceback (most recent call last):
  File "/Library/Python/2.7/site-packages/SQLAlchemy-0.9.8-py2.7-macosx-10.10-intel.egg/sqlalchemy/pool.py", line 567, in _finalize_fairy
    fairy._reset(pool)
  File "/Library/Python/2.7/site-packages/SQLAlchemy-0.9.8-py2.7-macosx-10.10-intel.egg/sqlalchemy/pool.py", line 701, in _reset
    pool._dialect.do_rollback(self)
  File "/Library/Python/2.7/site-packages/SQLAlchemy-0.9.8-py2.7-macosx-10.10-intel.egg/sqlalchemy/engine/default.py", line 406, in do_rollback
    dbapi_connection.rollback()
ProgrammingError: SQLite objects created in a thread can only be used in that same thread.The object was created in thread id 4404154368 and this is thread id 140735306928896
2014-11-10 14:48:56,852 pool _close_connection 255 : Exception closing connection <sqlite3.Connection object at 0x105611770>
Traceback (most recent call last):
  File "/Library/Python/2.7/site-packages/SQLAlchemy-0.9.8-py2.7-macosx-10.10-intel.egg/sqlalchemy/pool.py", line 250, in _close_connection
    self._dialect.do_close(connection)
  File "/Library/Python/2.7/site-packages/SQLAlchemy-0.9.8-py2.7-macosx-10.10-intel.egg/sqlalchemy/engine/default.py", line 412, in do_close
    dbapi_connection.close()
ProgrammingError: SQLite objects created in a thread can only be used in that same thread.The object was created in thread id 4404154368 and this is thread id 140735306928896
2014-11-12 07:45:26,853 pool _finalize_fairy 574 : Exception during reset or similar
Traceback (most recent call last):
  File "/Library/Python/2.7/site-packages/SQLAlchemy-0.9.8-py2.7-macosx-10.10-intel.egg/sqlalchemy/pool.py", line 567, in _finalize_fairy
    fairy._reset(pool)
  File "/Library/Python/2.7/site-packages/SQLAlchemy-0.9.8-py2.7-macosx-10.10-intel.egg/sqlalchemy/pool.py", line 701, in _reset
    pool._dialect.do_rollback(self)
  File "/Library/Python/2.7/site-packages/SQLAlchemy-0.9.8-py2.7-macosx-10.10-intel.egg/sqlalchemy/engine/default.py", line 406, in do_rollback
    dbapi_connection.rollback()
ProgrammingError: SQLite objects created in a thread can only be used in that same thread.The object was created in thread id 4568674304 and this is thread id 140735306928896
2014-11-12 07:45:26,857 pool _close_connection 255 : Exception closing connection <sqlite3.Connection object at 0x10f30b858>
Traceback (most recent call last):
  File "/Library/Python/2.7/site-packages/SQLAlchemy-0.9.8-py2.7-macosx-10.10-intel.egg/sqlalchemy/pool.py", line 250, in _close_connection
    self._dialect.do_close(connection)
  File "/Library/Python/2.7/site-packages/SQLAlchemy-0.9.8-py2.7-macosx-10.10-intel.egg/sqlalchemy/engine/default.py", line 412, in do_close
    dbapi_connection.close()
ProgrammingError: SQLite objects created in a thread can only be used in that same thread.The object was created in thread id 4568674304 and this is thread id 140735306928896
2014-11-12 20:44:03,289 pool _finalize_fairy 574 : Exception during reset or similar
Traceback (most recent call last):
  File "/Library/Python/2.7/site-packages/SQLAlchemy-0.9.8-py2.7-macosx-10.10-intel.egg/sqlalchemy/pool.py", line 567, in _finalize_fairy
    fairy._reset(pool)
  File "/Library/Python/2.7/site-packages/SQLAlchemy-0.9.8-py2.7-macosx-10.10-intel.egg/sqlalchemy/pool.py", line 701, in _reset
    pool._dialect.do_rollback(self)
  File "/Library/Python/2.7/site-packages/SQLAlchemy-0.9.8-py2.7-macosx-10.10-intel.egg/sqlalchemy/engine/default.py", line 406, in do_rollback
    dbapi_connection.rollback()
ProgrammingError: SQLite objects created in a thread can only be used in that same thread.The object was created in thread id 4547604480 and this is thread id 140735213748992
2014-11-12 20:44:03,294 pool _close_connection 255 : Exception closing connection <sqlite3.Connection object at 0x10d89e5a0>
Traceback (most recent call last):
  File "/Library/Python/2.7/site-packages/SQLAlchemy-0.9.8-py2.7-macosx-10.10-intel.egg/sqlalchemy/pool.py", line 250, in _close_connection
    self._dialect.do_close(connection)
  File "/Library/Python/2.7/site-packages/SQLAlchemy-0.9.8-py2.7-macosx-10.10-intel.egg/sqlalchemy/engine/default.py", line 412, in do_close
    dbapi_connection.close()
ProgrammingError: SQLite objects created in a thread can only be used in that same thread.The object was created in thread id 4547604480 and this is thread id 140735213748992
2014-11-17 11:00:52,360 pool _finalize_fairy 574 : Exception during reset or similar
Traceback (most recent call last):
  File "/Library/Python/2.7/site-packages/SQLAlchemy-0.9.8-py2.7-macosx-10.10-intel.egg/sqlalchemy/pool.py", line 567, in _finalize_fairy
    fairy._reset(pool)
  File "/Library/Python/2.7/site-packages/SQLAlchemy-0.9.8-py2.7-macosx-10.10-intel.egg/sqlalchemy/pool.py", line 701, in _reset
    pool._dialect.do_rollback(self)
  File "/Library/Python/2.7/site-packages/SQLAlchemy-0.9.8-py2.7-macosx-10.10-intel.egg/sqlalchemy/engine/default.py", line 406, in do_rollback
    dbapi_connection.rollback()
ProgrammingError: SQLite objects created in a thread can only be used in that same thread.The object was created in thread id 4539285504 and this is thread id 140735202427648
2014-11-17 11:00:52,363 pool _close_connection 255 : Exception closing connection <sqlite3.Connection object at 0x10d0a35a0>
Traceback (most recent call last):
  File "/Library/Python/2.7/site-packages/SQLAlchemy-0.9.8-py2.7-macosx-10.10-intel.egg/sqlalchemy/pool.py", line 250, in _close_connection
    self._dialect.do_close(connection)
  File "/Library/Python/2.7/site-packages/SQLAlchemy-0.9.8-py2.7-macosx-10.10-intel.egg/sqlalchemy/engine/default.py", line 412, in do_close
    dbapi_connection.close()
ProgrammingError: SQLite objects created in a thread can only be used in that same thread.The object was created in thread id 4539285504 and this is thread id 140735202427648
2014-11-20 18:55:40,940 pool _finalize_fairy 574 : Exception during reset or similar
Traceback (most recent call last):
  File "/Library/Python/2.7/site-packages/SQLAlchemy-0.9.8-py2.7-macosx-10.10-intel.egg/sqlalchemy/pool.py", line 567, in _finalize_fairy
    fairy._reset(pool)
  File "/Library/Python/2.7/site-packages/SQLAlchemy-0.9.8-py2.7-macosx-10.10-intel.egg/sqlalchemy/pool.py", line 701, in _reset
    pool._dialect.do_rollback(self)
  File "/Library/Python/2.7/site-packages/SQLAlchemy-0.9.8-py2.7-macosx-10.10-intel.egg/sqlalchemy/engine/default.py", line 406, in do_rollback
    dbapi_connection.rollback()
ProgrammingError: SQLite objects created in a thread can only be used in that same thread.The object was created in thread id 4357066752 and this is thread id 140735256826624
2014-11-20 18:55:40,943 pool _close_connection 255 : Exception closing connection <sqlite3.Connection object at 0x1022e85a0>
Traceback (most recent call last):
  File "/Library/Python/2.7/site-packages/SQLAlchemy-0.9.8-py2.7-macosx-10.10-intel.egg/sqlalchemy/pool.py", line 250, in _close_connection
    self._dialect.do_close(connection)
  File "/Library/Python/2.7/site-packages/SQLAlchemy-0.9.8-py2.7-macosx-10.10-intel.egg/sqlalchemy/engine/default.py", line 412, in do_close
    dbapi_connection.close()
ProgrammingError: SQLite objects created in a thread can only be used in that same thread.The object was created in thread id 4357066752 and this is thread id 140735256826624
2014-11-25 12:28:40,916 pool _finalize_fairy 574 : Exception during reset or similar
Traceback (most recent call last):
  File "/Library/Python/2.7/site-packages/SQLAlchemy-0.9.8-py2.7-macosx-10.10-intel.egg/sqlalchemy/pool.py", line 567, in _finalize_fairy
    fairy._reset(pool)
  File "/Library/Python/2.7/site-packages/SQLAlchemy-0.9.8-py2.7-macosx-10.10-intel.egg/sqlalchemy/pool.py", line 701, in _reset
    pool._dialect.do_rollback(self)
  File "/Library/Python/2.7/site-packages/SQLAlchemy-0.9.8-py2.7-macosx-10.10-intel.egg/sqlalchemy/engine/default.py", line 406, in do_rollback
    dbapi_connection.rollback()
ProgrammingError: SQLite objects created in a thread can only be used in that same thread.The object was created in thread id 4454354944 and this is thread id 140735155200768
2014-11-25 12:28:40,919 pool _close_connection 255 : Exception closing connection <sqlite3.Connection object at 0x10867f858>
Traceback (most recent call last):
  File "/Library/Python/2.7/site-packages/SQLAlchemy-0.9.8-py2.7-macosx-10.10-intel.egg/sqlalchemy/pool.py", line 250, in _close_connection
    self._dialect.do_close(connection)
  File "/Library/Python/2.7/site-packages/SQLAlchemy-0.9.8-py2.7-macosx-10.10-intel.egg/sqlalchemy/engine/default.py", line 412, in do_close
    dbapi_connection.close()
ProgrammingError: SQLite objects created in a thread can only be used in that same thread.The object was created in thread id 4454354944 and this is thread id 140735155200768
2014-12-01 07:15:11,666 pool _finalize_fairy 574 : Exception during reset or similar
Traceback (most recent call last):
  File "/Library/Python/2.7/site-packages/SQLAlchemy-0.9.8-py2.7-macosx-10.10-intel.egg/sqlalchemy/pool.py", line 567, in _finalize_fairy
    fairy._reset(pool)
  File "/Library/Python/2.7/site-packages/SQLAlchemy-0.9.8-py2.7-macosx-10.10-intel.egg/sqlalchemy/pool.py", line 701, in _reset
    pool._dialect.do_rollback(self)
  File "/Library/Python/2.7/site-packages/SQLAlchemy-0.9.8-py2.7-macosx-10.10-intel.egg/sqlalchemy/engine/default.py", line 406, in do_rollback
    dbapi_connection.rollback()
ProgrammingError: SQLite objects created in a thread can only be used in that same thread.The object was created in thread id 4475457536 and this is thread id 140735088231168
2014-12-01 07:15:11,670 pool _close_connection 255 : Exception closing connection <sqlite3.Connection object at 0x109b37770>
Traceback (most recent call last):
  File "/Library/Python/2.7/site-packages/SQLAlchemy-0.9.8-py2.7-macosx-10.10-intel.egg/sqlalchemy/pool.py", line 250, in _close_connection
    self._dialect.do_close(connection)
  File "/Library/Python/2.7/site-packages/SQLAlchemy-0.9.8-py2.7-macosx-10.10-intel.egg/sqlalchemy/engine/default.py", line 412, in do_close
    dbapi_connection.close()
ProgrammingError: SQLite objects created in a thread can only be used in that same thread.The object was created in thread id 4475457536 and this is thread id 140735088231168
2014-12-01 20:32:42,495 pool _finalize_fairy 574 : Exception during reset or similar
Traceback (most recent call last):
  File "/Library/Python/2.7/site-packages/SQLAlchemy-0.9.8-py2.7-macosx-10.10-intel.egg/sqlalchemy/pool.py", line 567, in _finalize_fairy
    fairy._reset(pool)
  File "/Library/Python/2.7/site-packages/SQLAlchemy-0.9.8-py2.7-macosx-10.10-intel.egg/sqlalchemy/pool.py", line 701, in _reset
    pool._dialect.do_rollback(self)
  File "/Library/Python/2.7/site-packages/SQLAlchemy-0.9.8-py2.7-macosx-10.10-intel.egg/sqlalchemy/engine/default.py", line 406, in do_rollback
    dbapi_connection.rollback()
ProgrammingError: SQLite objects created in a thread can only be used in that same thread.The object was created in thread id 4362080256 and this is thread id 140735088231168
2014-12-01 20:32:42,499 pool _close_connection 255 : Exception closing connection <sqlite3.Connection object at 0x102d75770>
Traceback (most recent call last):
  File "/Library/Python/2.7/site-packages/SQLAlchemy-0.9.8-py2.7-macosx-10.10-intel.egg/sqlalchemy/pool.py", line 250, in _close_connection
    self._dialect.do_close(connection)
  File "/Library/Python/2.7/site-packages/SQLAlchemy-0.9.8-py2.7-macosx-10.10-intel.egg/sqlalchemy/engine/default.py", line 412, in do_close
    dbapi_connection.close()
ProgrammingError: SQLite objects created in a thread can only be used in that same thread.The object was created in thread id 4362080256 and this is thread id 140735088231168
2014-12-01 20:33:06,912 pool _finalize_fairy 574 : Exception during reset or similar
Traceback (most recent call last):
  File "/Library/Python/2.7/site-packages/SQLAlchemy-0.9.8-py2.7-macosx-10.10-intel.egg/sqlalchemy/pool.py", line 567, in _finalize_fairy
    fairy._reset(pool)
  File "/Library/Python/2.7/site-packages/SQLAlchemy-0.9.8-py2.7-macosx-10.10-intel.egg/sqlalchemy/pool.py", line 701, in _reset
    pool._dialect.do_rollback(self)
  File "/Library/Python/2.7/site-packages/SQLAlchemy-0.9.8-py2.7-macosx-10.10-intel.egg/sqlalchemy/engine/default.py", line 406, in do_rollback
    dbapi_connection.rollback()
ProgrammingError: SQLite objects created in a thread can only be used in that same thread.The object was created in thread id 4429189120 and this is thread id 140735088231168
2014-12-01 20:33:06,913 pool _close_connection 255 : Exception closing connection <sqlite3.Connection object at 0x106d5e770>
Traceback (most recent call last):
  File "/Library/Python/2.7/site-packages/SQLAlchemy-0.9.8-py2.7-macosx-10.10-intel.egg/sqlalchemy/pool.py", line 250, in _close_connection
    self._dialect.do_close(connection)
  File "/Library/Python/2.7/site-packages/SQLAlchemy-0.9.8-py2.7-macosx-10.10-intel.egg/sqlalchemy/engine/default.py", line 412, in do_close
    dbapi_connection.close()
ProgrammingError: SQLite objects created in a thread can only be used in that same thread.The object was created in thread id 4429189120 and this is thread id 140735088231168
2014-12-02 16:15:43,873 pool _finalize_fairy 574 : Exception during reset or similar
Traceback (most recent call last):
  File "/Library/Python/2.7/site-packages/SQLAlchemy-0.9.8-py2.7-macosx-10.10-intel.egg/sqlalchemy/pool.py", line 567, in _finalize_fairy
    fairy._reset(pool)
  File "/Library/Python/2.7/site-packages/SQLAlchemy-0.9.8-py2.7-macosx-10.10-intel.egg/sqlalchemy/pool.py", line 701, in _reset
    pool._dialect.do_rollback(self)
  File "/Library/Python/2.7/site-packages/SQLAlchemy-0.9.8-py2.7-macosx-10.10-intel.egg/sqlalchemy/engine/default.py", line 406, in do_rollback
    dbapi_connection.rollback()
ProgrammingError: SQLite objects created in a thread can only be used in that same thread.The object was created in thread id 4444405760 and this is thread id 140735088231168
2014-12-02 16:15:43,877 pool _close_connection 255 : Exception closing connection <sqlite3.Connection object at 0x107c51770>
Traceback (most recent call last):
  File "/Library/Python/2.7/site-packages/SQLAlchemy-0.9.8-py2.7-macosx-10.10-intel.egg/sqlalchemy/pool.py", line 250, in _close_connection
    self._dialect.do_close(connection)
  File "/Library/Python/2.7/site-packages/SQLAlchemy-0.9.8-py2.7-macosx-10.10-intel.egg/sqlalchemy/engine/default.py", line 412, in do_close
    dbapi_connection.close()
ProgrammingError: SQLite objects created in a thread can only be used in that same thread.The object was created in thread id 4444405760 and this is thread id 140735088231168
2014-12-03 15:06:58,922 pool _finalize_fairy 574 : Exception during reset or similar
Traceback (most recent call last):
  File "/Library/Python/2.7/site-packages/SQLAlchemy-0.9.8-py2.7-macosx-10.10-intel.egg/sqlalchemy/pool.py", line 567, in _finalize_fairy
    fairy._reset(pool)
  File "/Library/Python/2.7/site-packages/SQLAlchemy-0.9.8-py2.7-macosx-10.10-intel.egg/sqlalchemy/pool.py", line 701, in _reset
    pool._dialect.do_rollback(self)
  File "/Library/Python/2.7/site-packages/SQLAlchemy-0.9.8-py2.7-macosx-10.10-intel.egg/sqlalchemy/engine/default.py", line 406, in do_rollback
    dbapi_connection.rollback()
ProgrammingError: SQLite objects created in a thread can only be used in that same thread.The object was created in thread id 4345303040 and this is thread id 140735088231168
2014-12-03 15:06:58,925 pool _close_connection 255 : Exception closing connection <sqlite3.Connection object at 0x101ec9770>
Traceback (most recent call last):
  File "/Library/Python/2.7/site-packages/SQLAlchemy-0.9.8-py2.7-macosx-10.10-intel.egg/sqlalchemy/pool.py", line 250, in _close_connection
    self._dialect.do_close(connection)
  File "/Library/Python/2.7/site-packages/SQLAlchemy-0.9.8-py2.7-macosx-10.10-intel.egg/sqlalchemy/engine/default.py", line 412, in do_close
    dbapi_connection.close()
ProgrammingError: SQLite objects created in a thread can only be used in that same thread.The object was created in thread id 4345303040 and this is thread id 140735088231168
2014-12-04 13:42:18,724 pool _finalize_fairy 574 : Exception during reset or similar
Traceback (most recent call last):
  File "/Library/Python/2.7/site-packages/SQLAlchemy-0.9.8-py2.7-macosx-10.10-intel.egg/sqlalchemy/pool.py", line 567, in _finalize_fairy
    fairy._reset(pool)
  File "/Library/Python/2.7/site-packages/SQLAlchemy-0.9.8-py2.7-macosx-10.10-intel.egg/sqlalchemy/pool.py", line 701, in _reset
    pool._dialect.do_rollback(self)
  File "/Library/Python/2.7/site-packages/SQLAlchemy-0.9.8-py2.7-macosx-10.10-intel.egg/sqlalchemy/engine/default.py", line 406, in do_rollback
    dbapi_connection.rollback()
ProgrammingError: SQLite objects created in a thread can only be used in that same thread.The object was created in thread id 4450160640 and this is thread id 140735088231168
2014-12-04 13:42:18,730 pool _close_connection 255 : Exception closing connection <sqlite3.Connection object at 0x1082af770>
Traceback (most recent call last):
  File "/Library/Python/2.7/site-packages/SQLAlchemy-0.9.8-py2.7-macosx-10.10-intel.egg/sqlalchemy/pool.py", line 250, in _close_connection
    self._dialect.do_close(connection)
  File "/Library/Python/2.7/site-packages/SQLAlchemy-0.9.8-py2.7-macosx-10.10-intel.egg/sqlalchemy/engine/default.py", line 412, in do_close
    dbapi_connection.close()
ProgrammingError: SQLite objects created in a thread can only be used in that same thread.The object was created in thread id 4450160640 and this is thread id 140735088231168
2014-12-12 09:46:16,403 pool _finalize_fairy 574 : Exception during reset or similar
Traceback (most recent call last):
  File "/Library/Python/2.7/site-packages/SQLAlchemy-0.9.8-py2.7-macosx-10.10-intel.egg/sqlalchemy/pool.py", line 567, in _finalize_fairy
    fairy._reset(pool)
  File "/Library/Python/2.7/site-packages/SQLAlchemy-0.9.8-py2.7-macosx-10.10-intel.egg/sqlalchemy/pool.py", line 701, in _reset
    pool._dialect.do_rollback(self)
  File "/Library/Python/2.7/site-packages/SQLAlchemy-0.9.8-py2.7-macosx-10.10-intel.egg/sqlalchemy/engine/default.py", line 406, in do_rollback
    dbapi_connection.rollback()
ProgrammingError: SQLite objects created in a thread can only be used in that same thread.The object was created in thread id 4490006528 and this is thread id 140735178208000
2014-12-12 09:46:16,406 pool _close_connection 255 : Exception closing connection <sqlite3.Connection object at 0x10a8a7770>
Traceback (most recent call last):
  File "/Library/Python/2.7/site-packages/SQLAlchemy-0.9.8-py2.7-macosx-10.10-intel.egg/sqlalchemy/pool.py", line 250, in _close_connection
    self._dialect.do_close(connection)
  File "/Library/Python/2.7/site-packages/SQLAlchemy-0.9.8-py2.7-macosx-10.10-intel.egg/sqlalchemy/engine/default.py", line 412, in do_close
    dbapi_connection.close()
ProgrammingError: SQLite objects created in a thread can only be used in that same thread.The object was created in thread id 4490006528 and this is thread id 140735178208000
2014-12-12 13:48:50,814 pool _finalize_fairy 574 : Exception during reset or similar
Traceback (most recent call last):
  File "/Library/Python/2.7/site-packages/SQLAlchemy-0.9.8-py2.7-macosx-10.10-intel.egg/sqlalchemy/pool.py", line 567, in _finalize_fairy
    fairy._reset(pool)
  File "/Library/Python/2.7/site-packages/SQLAlchemy-0.9.8-py2.7-macosx-10.10-intel.egg/sqlalchemy/pool.py", line 701, in _reset
    pool._dialect.do_rollback(self)
  File "/Library/Python/2.7/site-packages/SQLAlchemy-0.9.8-py2.7-macosx-10.10-intel.egg/sqlalchemy/engine/default.py", line 406, in do_rollback
    dbapi_connection.rollback()
ProgrammingError: SQLite objects created in a thread can only be used in that same thread.The object was created in thread id 4523560960 and this is thread id 140735178208000
2014-12-12 13:48:50,820 pool _close_connection 255 : Exception closing connection <sqlite3.Connection object at 0x10c827770>
Traceback (most recent call last):
  File "/Library/Python/2.7/site-packages/SQLAlchemy-0.9.8-py2.7-macosx-10.10-intel.egg/sqlalchemy/pool.py", line 250, in _close_connection
    self._dialect.do_close(connection)
  File "/Library/Python/2.7/site-packages/SQLAlchemy-0.9.8-py2.7-macosx-10.10-intel.egg/sqlalchemy/engine/default.py", line 412, in do_close
    dbapi_connection.close()
ProgrammingError: SQLite objects created in a thread can only be used in that same thread.The object was created in thread id 4523560960 and this is thread id 140735178208000
2014-12-15 13:44:37,409 pool _finalize_fairy 574 : Exception during reset or similar
Traceback (most recent call last):
  File "/Library/Python/2.7/site-packages/SQLAlchemy-0.9.8-py2.7-macosx-10.10-intel.egg/sqlalchemy/pool.py", line 567, in _finalize_fairy
    fairy._reset(pool)
  File "/Library/Python/2.7/site-packages/SQLAlchemy-0.9.8-py2.7-macosx-10.10-intel.egg/sqlalchemy/pool.py", line 701, in _reset
    pool._dialect.do_rollback(self)
  File "/Library/Python/2.7/site-packages/SQLAlchemy-0.9.8-py2.7-macosx-10.10-intel.egg/sqlalchemy/engine/default.py", line 406, in do_rollback
    dbapi_connection.rollback()
ProgrammingError: SQLite objects created in a thread can only be used in that same thread.The object was created in thread id 4567601152 and this is thread id 140735178208000
2014-12-15 13:44:37,414 pool _close_connection 255 : Exception closing connection <sqlite3.Connection object at 0x10f2e5770>
Traceback (most recent call last):
  File "/Library/Python/2.7/site-packages/SQLAlchemy-0.9.8-py2.7-macosx-10.10-intel.egg/sqlalchemy/pool.py", line 250, in _close_connection
    self._dialect.do_close(connection)
  File "/Library/Python/2.7/site-packages/SQLAlchemy-0.9.8-py2.7-macosx-10.10-intel.egg/sqlalchemy/engine/default.py", line 412, in do_close
    dbapi_connection.close()
ProgrammingError: SQLite objects created in a thread can only be used in that same thread.The object was created in thread id 4567601152 and this is thread id 140735178208000
2014-12-15 13:47:36,649 pool _finalize_fairy 574 : Exception during reset or similar
Traceback (most recent call last):
  File "/Library/Python/2.7/site-packages/SQLAlchemy-0.9.8-py2.7-macosx-10.10-intel.egg/sqlalchemy/pool.py", line 567, in _finalize_fairy
    fairy._reset(pool)
  File "/Library/Python/2.7/site-packages/SQLAlchemy-0.9.8-py2.7-macosx-10.10-intel.egg/sqlalchemy/pool.py", line 701, in _reset
    pool._dialect.do_rollback(self)
  File "/Library/Python/2.7/site-packages/SQLAlchemy-0.9.8-py2.7-macosx-10.10-intel.egg/sqlalchemy/engine/default.py", line 406, in do_rollback
    dbapi_connection.rollback()
ProgrammingError: SQLite objects created in a thread can only be used in that same thread.The object was created in thread id 4450160640 and this is thread id 140735178208000
2014-12-15 13:47:36,650 pool _close_connection 255 : Exception closing connection <sqlite3.Connection object at 0x108230858>
Traceback (most recent call last):
  File "/Library/Python/2.7/site-packages/SQLAlchemy-0.9.8-py2.7-macosx-10.10-intel.egg/sqlalchemy/pool.py", line 250, in _close_connection
    self._dialect.do_close(connection)
  File "/Library/Python/2.7/site-packages/SQLAlchemy-0.9.8-py2.7-macosx-10.10-intel.egg/sqlalchemy/engine/default.py", line 412, in do_close
    dbapi_connection.close()
ProgrammingError: SQLite objects created in a thread can only be used in that same thread.The object was created in thread id 4450160640 and this is thread id 140735178208000
2014-12-16 09:59:07,210 pool _finalize_fairy 574 : Exception during reset or similar
Traceback (most recent call last):
  File "/Library/Python/2.7/site-packages/SQLAlchemy-0.9.8-py2.7-macosx-10.10-intel.egg/sqlalchemy/pool.py", line 567, in _finalize_fairy
    fairy._reset(pool)
  File "/Library/Python/2.7/site-packages/SQLAlchemy-0.9.8-py2.7-macosx-10.10-intel.egg/sqlalchemy/pool.py", line 701, in _reset
    pool._dialect.do_rollback(self)
  File "/Library/Python/2.7/site-packages/SQLAlchemy-0.9.8-py2.7-macosx-10.10-intel.egg/sqlalchemy/engine/default.py", line 406, in do_rollback
    dbapi_connection.rollback()
ProgrammingError: SQLite objects created in a thread can only be used in that same thread.The object was created in thread id 4483715072 and this is thread id 140735178208000
2014-12-16 09:59:07,214 pool _close_connection 255 : Exception closing connection <sqlite3.Connection object at 0x10a258770>
Traceback (most recent call last):
  File "/Library/Python/2.7/site-packages/SQLAlchemy-0.9.8-py2.7-macosx-10.10-intel.egg/sqlalchemy/pool.py", line 250, in _close_connection
    self._dialect.do_close(connection)
  File "/Library/Python/2.7/site-packages/SQLAlchemy-0.9.8-py2.7-macosx-10.10-intel.egg/sqlalchemy/engine/default.py", line 412, in do_close
    dbapi_connection.close()
ProgrammingError: SQLite objects created in a thread can only be used in that same thread.The object was created in thread id 4483715072 and this is thread id 140735178208000
2014-12-16 10:51:55,484 pool _finalize_fairy 574 : Exception during reset or similar
Traceback (most recent call last):
  File "/Library/Python/2.7/site-packages/SQLAlchemy-0.9.8-py2.7-macosx-10.10-intel.egg/sqlalchemy/pool.py", line 567, in _finalize_fairy
    fairy._reset(pool)
  File "/Library/Python/2.7/site-packages/SQLAlchemy-0.9.8-py2.7-macosx-10.10-intel.egg/sqlalchemy/pool.py", line 701, in _reset
    pool._dialect.do_rollback(self)
  File "/Library/Python/2.7/site-packages/SQLAlchemy-0.9.8-py2.7-macosx-10.10-intel.egg/sqlalchemy/engine/default.py", line 406, in do_rollback
    dbapi_connection.rollback()
ProgrammingError: SQLite objects created in a thread can only be used in that same thread.The object was created in thread id 4596961280 and this is thread id 140735178208000
2014-12-16 10:51:55,488 pool _close_connection 255 : Exception closing connection <sqlite3.Connection object at 0x110ec1770>
Traceback (most recent call last):
  File "/Library/Python/2.7/site-packages/SQLAlchemy-0.9.8-py2.7-macosx-10.10-intel.egg/sqlalchemy/pool.py", line 250, in _close_connection
    self._dialect.do_close(connection)
  File "/Library/Python/2.7/site-packages/SQLAlchemy-0.9.8-py2.7-macosx-10.10-intel.egg/sqlalchemy/engine/default.py", line 412, in do_close
    dbapi_connection.close()
ProgrammingError: SQLite objects created in a thread can only be used in that same thread.The object was created in thread id 4596961280 and this is thread id 140735178208000
2014-12-17 09:28:38,952 pool _finalize_fairy 574 : Exception during reset or similar
Traceback (most recent call last):
  File "/Library/Python/2.7/site-packages/SQLAlchemy-0.9.8-py2.7-macosx-10.10-intel.egg/sqlalchemy/pool.py", line 567, in _finalize_fairy
    fairy._reset(pool)
  File "/Library/Python/2.7/site-packages/SQLAlchemy-0.9.8-py2.7-macosx-10.10-intel.egg/sqlalchemy/pool.py", line 701, in _reset
    pool._dialect.do_rollback(self)
  File "/Library/Python/2.7/site-packages/SQLAlchemy-0.9.8-py2.7-macosx-10.10-intel.egg/sqlalchemy/engine/default.py", line 406, in do_rollback
    dbapi_connection.rollback()
ProgrammingError: SQLite objects created in a thread can only be used in that same thread.The object was created in thread id 4508880896 and this is thread id 140735178208000
2014-12-17 09:28:38,955 pool _close_connection 255 : Exception closing connection <sqlite3.Connection object at 0x10baed770>
Traceback (most recent call last):
  File "/Library/Python/2.7/site-packages/SQLAlchemy-0.9.8-py2.7-macosx-10.10-intel.egg/sqlalchemy/pool.py", line 250, in _close_connection
    self._dialect.do_close(connection)
  File "/Library/Python/2.7/site-packages/SQLAlchemy-0.9.8-py2.7-macosx-10.10-intel.egg/sqlalchemy/engine/default.py", line 412, in do_close
    dbapi_connection.close()
ProgrammingError: SQLite objects created in a thread can only be used in that same thread.The object was created in thread id 4508880896 and this is thread id 140735178208000
2014-12-17 09:41:52,754 pool _finalize_fairy 574 : Exception during reset or similar
Traceback (most recent call last):
  File "/Library/Python/2.7/site-packages/SQLAlchemy-0.9.8-py2.7-macosx-10.10-intel.egg/sqlalchemy/pool.py", line 567, in _finalize_fairy
    fairy._reset(pool)
  File "/Library/Python/2.7/site-packages/SQLAlchemy-0.9.8-py2.7-macosx-10.10-intel.egg/sqlalchemy/pool.py", line 701, in _reset
    pool._dialect.do_rollback(self)
  File "/Library/Python/2.7/site-packages/SQLAlchemy-0.9.8-py2.7-macosx-10.10-intel.egg/sqlalchemy/engine/default.py", line 406, in do_rollback
    dbapi_connection.rollback()
ProgrammingError: SQLite objects created in a thread can only be used in that same thread.The object was created in thread id 4427091968 and this is thread id 140735178208000
2014-12-17 09:41:52,758 pool _close_connection 255 : Exception closing connection <sqlite3.Connection object at 0x106c37770>
Traceback (most recent call last):
  File "/Library/Python/2.7/site-packages/SQLAlchemy-0.9.8-py2.7-macosx-10.10-intel.egg/sqlalchemy/pool.py", line 250, in _close_connection
    self._dialect.do_close(connection)
  File "/Library/Python/2.7/site-packages/SQLAlchemy-0.9.8-py2.7-macosx-10.10-intel.egg/sqlalchemy/engine/default.py", line 412, in do_close
    dbapi_connection.close()
ProgrammingError: SQLite objects created in a thread can only be used in that same thread.The object was created in thread id 4427091968 and this is thread id 140735178208000
2014-12-19 09:17:46,936 pool _finalize_fairy 574 : Exception during reset or similar
Traceback (most recent call last):
  File "/Library/Python/2.7/site-packages/SQLAlchemy-0.9.8-py2.7-macosx-10.10-intel.egg/sqlalchemy/pool.py", line 567, in _finalize_fairy
    fairy._reset(pool)
  File "/Library/Python/2.7/site-packages/SQLAlchemy-0.9.8-py2.7-macosx-10.10-intel.egg/sqlalchemy/pool.py", line 701, in _reset
    pool._dialect.do_rollback(self)
  File "/Library/Python/2.7/site-packages/SQLAlchemy-0.9.8-py2.7-macosx-10.10-intel.egg/sqlalchemy/engine/default.py", line 406, in do_rollback
    dbapi_connection.rollback()
ProgrammingError: SQLite objects created in a thread can only be used in that same thread.The object was created in thread id 4336914432 and this is thread id 140735178208000
2014-12-19 09:17:46,940 pool _close_connection 255 : Exception closing connection <sqlite3.Connection object at 0x1015f7770>
Traceback (most recent call last):
  File "/Library/Python/2.7/site-packages/SQLAlchemy-0.9.8-py2.7-macosx-10.10-intel.egg/sqlalchemy/pool.py", line 250, in _close_connection
    self._dialect.do_close(connection)
  File "/Library/Python/2.7/site-packages/SQLAlchemy-0.9.8-py2.7-macosx-10.10-intel.egg/sqlalchemy/engine/default.py", line 412, in do_close
    dbapi_connection.close()
ProgrammingError: SQLite objects created in a thread can only be used in that same thread.The object was created in thread id 4336914432 and this is thread id 140735178208000
2014-12-19 11:42:25,101 pool _finalize_fairy 574 : Exception during reset or similar
Traceback (most recent call last):
  File "/Library/Python/2.7/site-packages/SQLAlchemy-0.9.8-py2.7-macosx-10.10-intel.egg/sqlalchemy/pool.py", line 567, in _finalize_fairy
    fairy._reset(pool)
  File "/Library/Python/2.7/site-packages/SQLAlchemy-0.9.8-py2.7-macosx-10.10-intel.egg/sqlalchemy/pool.py", line 701, in _reset
    pool._dialect.do_rollback(self)
  File "/Library/Python/2.7/site-packages/SQLAlchemy-0.9.8-py2.7-macosx-10.10-intel.egg/sqlalchemy/engine/default.py", line 406, in do_rollback
    dbapi_connection.rollback()
ProgrammingError: SQLite objects created in a thread can only be used in that same thread.The object was created in thread id 4366274560 and this is thread id 140735178208000
2014-12-19 11:42:25,105 pool _close_connection 255 : Exception closing connection <sqlite3.Connection object at 0x1031cf770>
Traceback (most recent call last):
  File "/Library/Python/2.7/site-packages/SQLAlchemy-0.9.8-py2.7-macosx-10.10-intel.egg/sqlalchemy/pool.py", line 250, in _close_connection
    self._dialect.do_close(connection)
  File "/Library/Python/2.7/site-packages/SQLAlchemy-0.9.8-py2.7-macosx-10.10-intel.egg/sqlalchemy/engine/default.py", line 412, in do_close
    dbapi_connection.close()
ProgrammingError: SQLite objects created in a thread can only be used in that same thread.The object was created in thread id 4366274560 and this is thread id 140735178208000
2014-12-19 14:40:37,711 pool _finalize_fairy 574 : Exception during reset or similar
Traceback (most recent call last):
  File "/Library/Python/2.7/site-packages/SQLAlchemy-0.9.8-py2.7-macosx-10.10-intel.egg/sqlalchemy/pool.py", line 567, in _finalize_fairy
    fairy._reset(pool)
  File "/Library/Python/2.7/site-packages/SQLAlchemy-0.9.8-py2.7-macosx-10.10-intel.egg/sqlalchemy/pool.py", line 701, in _reset
    pool._dialect.do_rollback(self)
  File "/Library/Python/2.7/site-packages/SQLAlchemy-0.9.8-py2.7-macosx-10.10-intel.egg/sqlalchemy/engine/default.py", line 406, in do_rollback
    dbapi_connection.rollback()
ProgrammingError: SQLite objects created in a thread can only be used in that same thread.The object was created in thread id 4448063488 and this is thread id 140735178208000
2014-12-19 14:40:37,715 pool _close_connection 255 : Exception closing connection <sqlite3.Connection object at 0x1080d9770>
Traceback (most recent call last):
  File "/Library/Python/2.7/site-packages/SQLAlchemy-0.9.8-py2.7-macosx-10.10-intel.egg/sqlalchemy/pool.py", line 250, in _close_connection
    self._dialect.do_close(connection)
  File "/Library/Python/2.7/site-packages/SQLAlchemy-0.9.8-py2.7-macosx-10.10-intel.egg/sqlalchemy/engine/default.py", line 412, in do_close
    dbapi_connection.close()
ProgrammingError: SQLite objects created in a thread can only be used in that same thread.The object was created in thread id 4448063488 and this is thread id 140735178208000
2014-12-19 15:07:24,855 pool _finalize_fairy 574 : Exception during reset or similar
Traceback (most recent call last):
  File "/Library/Python/2.7/site-packages/SQLAlchemy-0.9.8-py2.7-macosx-10.10-intel.egg/sqlalchemy/pool.py", line 567, in _finalize_fairy
    fairy._reset(pool)
  File "/Library/Python/2.7/site-packages/SQLAlchemy-0.9.8-py2.7-macosx-10.10-intel.egg/sqlalchemy/pool.py", line 701, in _reset
    pool._dialect.do_rollback(self)
  File "/Library/Python/2.7/site-packages/SQLAlchemy-0.9.8-py2.7-macosx-10.10-intel.egg/sqlalchemy/engine/default.py", line 406, in do_rollback
    dbapi_connection.rollback()
ProgrammingError: SQLite objects created in a thread can only be used in that same thread.The object was created in thread id 4401926144 and this is thread id 140735178208000
2014-12-19 15:07:24,860 pool _close_connection 255 : Exception closing connection <sqlite3.Connection object at 0x10540b770>
Traceback (most recent call last):
  File "/Library/Python/2.7/site-packages/SQLAlchemy-0.9.8-py2.7-macosx-10.10-intel.egg/sqlalchemy/pool.py", line 250, in _close_connection
    self._dialect.do_close(connection)
  File "/Library/Python/2.7/site-packages/SQLAlchemy-0.9.8-py2.7-macosx-10.10-intel.egg/sqlalchemy/engine/default.py", line 412, in do_close
    dbapi_connection.close()
ProgrammingError: SQLite objects created in a thread can only be used in that same thread.The object was created in thread id 4401926144 and this is thread id 140735178208000
2014-12-22 08:42:53,697 pool _finalize_fairy 574 : Exception during reset or similar
Traceback (most recent call last):
  File "/Library/Python/2.7/site-packages/SQLAlchemy-0.9.8-py2.7-macosx-10.10-intel.egg/sqlalchemy/pool.py", line 567, in _finalize_fairy
    fairy._reset(pool)
  File "/Library/Python/2.7/site-packages/SQLAlchemy-0.9.8-py2.7-macosx-10.10-intel.egg/sqlalchemy/pool.py", line 701, in _reset
    pool._dialect.do_rollback(self)
  File "/Library/Python/2.7/site-packages/SQLAlchemy-0.9.8-py2.7-macosx-10.10-intel.egg/sqlalchemy/engine/default.py", line 406, in do_rollback
    dbapi_connection.rollback()
ProgrammingError: SQLite objects created in a thread can only be used in that same thread.The object was created in thread id 4334817280 and this is thread id 140735147995904
2014-12-22 08:42:53,699 pool _close_connection 255 : Exception closing connection <sqlite3.Connection object at 0x1014b8770>
Traceback (most recent call last):
  File "/Library/Python/2.7/site-packages/SQLAlchemy-0.9.8-py2.7-macosx-10.10-intel.egg/sqlalchemy/pool.py", line 250, in _close_connection
    self._dialect.do_close(connection)
  File "/Library/Python/2.7/site-packages/SQLAlchemy-0.9.8-py2.7-macosx-10.10-intel.egg/sqlalchemy/engine/default.py", line 412, in do_close
    dbapi_connection.close()
ProgrammingError: SQLite objects created in a thread can only be used in that same thread.The object was created in thread id 4334817280 and this is thread id 140735147995904
2014-12-22 10:06:17,155 pool _finalize_fairy 574 : Exception during reset or similar
Traceback (most recent call last):
  File "/Library/Python/2.7/site-packages/SQLAlchemy-0.9.8-py2.7-macosx-10.10-intel.egg/sqlalchemy/pool.py", line 567, in _finalize_fairy
    fairy._reset(pool)
  File "/Library/Python/2.7/site-packages/SQLAlchemy-0.9.8-py2.7-macosx-10.10-intel.egg/sqlalchemy/pool.py", line 701, in _reset
    pool._dialect.do_rollback(self)
  File "/Library/Python/2.7/site-packages/SQLAlchemy-0.9.8-py2.7-macosx-10.10-intel.egg/sqlalchemy/engine/default.py", line 406, in do_rollback
    dbapi_connection.rollback()
ProgrammingError: SQLite objects created in a thread can only be used in that same thread.The object was created in thread id 4410314752 and this is thread id 140735147995904
2014-12-22 10:06:17,159 pool _close_connection 255 : Exception closing connection <sqlite3.Connection object at 0x105b9c770>
Traceback (most recent call last):
  File "/Library/Python/2.7/site-packages/SQLAlchemy-0.9.8-py2.7-macosx-10.10-intel.egg/sqlalchemy/pool.py", line 250, in _close_connection
    self._dialect.do_close(connection)
  File "/Library/Python/2.7/site-packages/SQLAlchemy-0.9.8-py2.7-macosx-10.10-intel.egg/sqlalchemy/engine/default.py", line 412, in do_close
    dbapi_connection.close()
ProgrammingError: SQLite objects created in a thread can only be used in that same thread.The object was created in thread id 4410314752 and this is thread id 140735147995904
2014-12-22 17:05:38,513 pool _finalize_fairy 574 : Exception during reset or similar
Traceback (most recent call last):
  File "/Library/Python/2.7/site-packages/SQLAlchemy-0.9.8-py2.7-macosx-10.10-intel.egg/sqlalchemy/pool.py", line 567, in _finalize_fairy
    fairy._reset(pool)
  File "/Library/Python/2.7/site-packages/SQLAlchemy-0.9.8-py2.7-macosx-10.10-intel.egg/sqlalchemy/pool.py", line 701, in _reset
    pool._dialect.do_rollback(self)
  File "/Library/Python/2.7/site-packages/SQLAlchemy-0.9.8-py2.7-macosx-10.10-intel.egg/sqlalchemy/engine/default.py", line 406, in do_rollback
    dbapi_connection.rollback()
ProgrammingError: SQLite objects created in a thread can only be used in that same thread.The object was created in thread id 4387246080 and this is thread id 140735147995904
2014-12-22 17:05:38,518 pool _close_connection 255 : Exception closing connection <sqlite3.Connection object at 0x1045ed770>
Traceback (most recent call last):
  File "/Library/Python/2.7/site-packages/SQLAlchemy-0.9.8-py2.7-macosx-10.10-intel.egg/sqlalchemy/pool.py", line 250, in _close_connection
    self._dialect.do_close(connection)
  File "/Library/Python/2.7/site-packages/SQLAlchemy-0.9.8-py2.7-macosx-10.10-intel.egg/sqlalchemy/engine/default.py", line 412, in do_close
    dbapi_connection.close()
ProgrammingError: SQLite objects created in a thread can only be used in that same thread.The object was created in thread id 4387246080 and this is thread id 140735147995904
2014-12-22 17:05:45,805 pool _finalize_fairy 574 : Exception during reset or similar
Traceback (most recent call last):
  File "/Library/Python/2.7/site-packages/SQLAlchemy-0.9.8-py2.7-macosx-10.10-intel.egg/sqlalchemy/pool.py", line 567, in _finalize_fairy
    fairy._reset(pool)
  File "/Library/Python/2.7/site-packages/SQLAlchemy-0.9.8-py2.7-macosx-10.10-intel.egg/sqlalchemy/pool.py", line 701, in _reset
    pool._dialect.do_rollback(self)
  File "/Library/Python/2.7/site-packages/SQLAlchemy-0.9.8-py2.7-macosx-10.10-intel.egg/sqlalchemy/engine/default.py", line 406, in do_rollback
    dbapi_connection.rollback()
ProgrammingError: SQLite objects created in a thread can only be used in that same thread.The object was created in thread id 4397731840 and this is thread id 140735147995904
2014-12-22 17:05:45,807 pool _close_connection 255 : Exception closing connection <sqlite3.Connection object at 0x104f51770>
Traceback (most recent call last):
  File "/Library/Python/2.7/site-packages/SQLAlchemy-0.9.8-py2.7-macosx-10.10-intel.egg/sqlalchemy/pool.py", line 250, in _close_connection
    self._dialect.do_close(connection)
  File "/Library/Python/2.7/site-packages/SQLAlchemy-0.9.8-py2.7-macosx-10.10-intel.egg/sqlalchemy/engine/default.py", line 412, in do_close
    dbapi_connection.close()
ProgrammingError: SQLite objects created in a thread can only be used in that same thread.The object was created in thread id 4397731840 and this is thread id 140735147995904
2014-12-23 12:25:32,867 pool _finalize_fairy 574 : Exception during reset or similar
Traceback (most recent call last):
  File "/Library/Python/2.7/site-packages/SQLAlchemy-0.9.8-py2.7-macosx-10.10-intel.egg/sqlalchemy/pool.py", line 567, in _finalize_fairy
    fairy._reset(pool)
  File "/Library/Python/2.7/site-packages/SQLAlchemy-0.9.8-py2.7-macosx-10.10-intel.egg/sqlalchemy/pool.py", line 701, in _reset
    pool._dialect.do_rollback(self)
  File "/Library/Python/2.7/site-packages/SQLAlchemy-0.9.8-py2.7-macosx-10.10-intel.egg/sqlalchemy/engine/default.py", line 406, in do_rollback
    dbapi_connection.rollback()
ProgrammingError: SQLite objects created in a thread can only be used in that same thread.The object was created in thread id 4504686592 and this is thread id 140735147995904
2014-12-23 12:25:32,873 pool _close_connection 255 : Exception closing connection <sqlite3.Connection object at 0x10b653770>
Traceback (most recent call last):
  File "/Library/Python/2.7/site-packages/SQLAlchemy-0.9.8-py2.7-macosx-10.10-intel.egg/sqlalchemy/pool.py", line 250, in _close_connection
    self._dialect.do_close(connection)
  File "/Library/Python/2.7/site-packages/SQLAlchemy-0.9.8-py2.7-macosx-10.10-intel.egg/sqlalchemy/engine/default.py", line 412, in do_close
    dbapi_connection.close()
ProgrammingError: SQLite objects created in a thread can only be used in that same thread.The object was created in thread id 4504686592 and this is thread id 140735147995904
2014-12-23 16:02:03,255 pool _finalize_fairy 574 : Exception during reset or similar
Traceback (most recent call last):
  File "/Library/Python/2.7/site-packages/SQLAlchemy-0.9.8-py2.7-macosx-10.10-intel.egg/sqlalchemy/pool.py", line 567, in _finalize_fairy
    fairy._reset(pool)
  File "/Library/Python/2.7/site-packages/SQLAlchemy-0.9.8-py2.7-macosx-10.10-intel.egg/sqlalchemy/pool.py", line 701, in _reset
    pool._dialect.do_rollback(self)
  File "/Library/Python/2.7/site-packages/SQLAlchemy-0.9.8-py2.7-macosx-10.10-intel.egg/sqlalchemy/engine/default.py", line 406, in do_rollback
    dbapi_connection.rollback()
ProgrammingError: SQLite objects created in a thread can only be used in that same thread.The object was created in thread id 4378857472 and this is thread id 140735147995904
2014-12-23 16:02:03,260 pool _close_connection 255 : Exception closing connection <sqlite3.Connection object at 0x103df0770>
Traceback (most recent call last):
  File "/Library/Python/2.7/site-packages/SQLAlchemy-0.9.8-py2.7-macosx-10.10-intel.egg/sqlalchemy/pool.py", line 250, in _close_connection
    self._dialect.do_close(connection)
  File "/Library/Python/2.7/site-packages/SQLAlchemy-0.9.8-py2.7-macosx-10.10-intel.egg/sqlalchemy/engine/default.py", line 412, in do_close
    dbapi_connection.close()
ProgrammingError: SQLite objects created in a thread can only be used in that same thread.The object was created in thread id 4378857472 and this is thread id 140735147995904
2014-12-24 10:17:46,247 pool _finalize_fairy 574 : Exception during reset or similar
Traceback (most recent call last):
  File "/Library/Python/2.7/site-packages/SQLAlchemy-0.9.8-py2.7-macosx-10.10-intel.egg/sqlalchemy/pool.py", line 567, in _finalize_fairy
    fairy._reset(pool)
  File "/Library/Python/2.7/site-packages/SQLAlchemy-0.9.8-py2.7-macosx-10.10-intel.egg/sqlalchemy/pool.py", line 701, in _reset
    pool._dialect.do_rollback(self)
  File "/Library/Python/2.7/site-packages/SQLAlchemy-0.9.8-py2.7-macosx-10.10-intel.egg/sqlalchemy/engine/default.py", line 406, in do_rollback
    dbapi_connection.rollback()
ProgrammingError: SQLite objects created in a thread can only be used in that same thread.The object was created in thread id 4513075200 and this is thread id 140735191470848
2014-12-24 10:17:46,249 pool _close_connection 255 : Exception closing connection <sqlite3.Connection object at 0x10bd65770>
Traceback (most recent call last):
  File "/Library/Python/2.7/site-packages/SQLAlchemy-0.9.8-py2.7-macosx-10.10-intel.egg/sqlalchemy/pool.py", line 250, in _close_connection
    self._dialect.do_close(connection)
  File "/Library/Python/2.7/site-packages/SQLAlchemy-0.9.8-py2.7-macosx-10.10-intel.egg/sqlalchemy/engine/default.py", line 412, in do_close
    dbapi_connection.close()
ProgrammingError: SQLite objects created in a thread can only be used in that same thread.The object was created in thread id 4513075200 and this is thread id 140735191470848
2014-12-24 10:57:24,991 pool _finalize_fairy 574 : Exception during reset or similar
Traceback (most recent call last):
  File "/Library/Python/2.7/site-packages/SQLAlchemy-0.9.8-py2.7-macosx-10.10-intel.egg/sqlalchemy/pool.py", line 567, in _finalize_fairy
    fairy._reset(pool)
  File "/Library/Python/2.7/site-packages/SQLAlchemy-0.9.8-py2.7-macosx-10.10-intel.egg/sqlalchemy/pool.py", line 701, in _reset
    pool._dialect.do_rollback(self)
  File "/Library/Python/2.7/site-packages/SQLAlchemy-0.9.8-py2.7-macosx-10.10-intel.egg/sqlalchemy/engine/default.py", line 406, in do_rollback
    dbapi_connection.rollback()
ProgrammingError: SQLite objects created in a thread can only be used in that same thread.The object was created in thread id 4506783744 and this is thread id 140735191470848
2014-12-24 10:57:24,992 pool _close_connection 255 : Exception closing connection <sqlite3.Connection object at 0x10b771770>
Traceback (most recent call last):
  File "/Library/Python/2.7/site-packages/SQLAlchemy-0.9.8-py2.7-macosx-10.10-intel.egg/sqlalchemy/pool.py", line 250, in _close_connection
    self._dialect.do_close(connection)
  File "/Library/Python/2.7/site-packages/SQLAlchemy-0.9.8-py2.7-macosx-10.10-intel.egg/sqlalchemy/engine/default.py", line 412, in do_close
    dbapi_connection.close()
ProgrammingError: SQLite objects created in a thread can only be used in that same thread.The object was created in thread id 4506783744 and this is thread id 140735191470848
2014-12-24 13:03:11,834 pool _finalize_fairy 574 : Exception during reset or similar
Traceback (most recent call last):
  File "/Library/Python/2.7/site-packages/SQLAlchemy-0.9.8-py2.7-macosx-10.10-intel.egg/sqlalchemy/pool.py", line 567, in _finalize_fairy
    fairy._reset(pool)
  File "/Library/Python/2.7/site-packages/SQLAlchemy-0.9.8-py2.7-macosx-10.10-intel.egg/sqlalchemy/pool.py", line 701, in _reset
    pool._dialect.do_rollback(self)
  File "/Library/Python/2.7/site-packages/SQLAlchemy-0.9.8-py2.7-macosx-10.10-intel.egg/sqlalchemy/engine/default.py", line 406, in do_rollback
    dbapi_connection.rollback()
ProgrammingError: SQLite objects created in a thread can only be used in that same thread.The object was created in thread id 4368371712 and this is thread id 140735191470848
2014-12-24 13:03:11,841 pool _close_connection 255 : Exception closing connection <sqlite3.Connection object at 0x1033c0770>
Traceback (most recent call last):
  File "/Library/Python/2.7/site-packages/SQLAlchemy-0.9.8-py2.7-macosx-10.10-intel.egg/sqlalchemy/pool.py", line 250, in _close_connection
    self._dialect.do_close(connection)
  File "/Library/Python/2.7/site-packages/SQLAlchemy-0.9.8-py2.7-macosx-10.10-intel.egg/sqlalchemy/engine/default.py", line 412, in do_close
    dbapi_connection.close()
ProgrammingError: SQLite objects created in a thread can only be used in that same thread.The object was created in thread id 4368371712 and this is thread id 140735191470848
2014-12-29 12:38:51,601 pool _finalize_fairy 574 : Exception during reset or similar
Traceback (most recent call last):
  File "/Library/Python/2.7/site-packages/SQLAlchemy-0.9.8-py2.7-macosx-10.10-intel.egg/sqlalchemy/pool.py", line 567, in _finalize_fairy
    fairy._reset(pool)
  File "/Library/Python/2.7/site-packages/SQLAlchemy-0.9.8-py2.7-macosx-10.10-intel.egg/sqlalchemy/pool.py", line 701, in _reset
    pool._dialect.do_rollback(self)
  File "/Library/Python/2.7/site-packages/SQLAlchemy-0.9.8-py2.7-macosx-10.10-intel.egg/sqlalchemy/engine/default.py", line 406, in do_rollback
    dbapi_connection.rollback()
ProgrammingError: SQLite objects created in a thread can only be used in that same thread.The object was created in thread id 4443869184 and this is thread id 140735276184320
2014-12-29 12:38:51,606 pool _close_connection 255 : Exception closing connection <sqlite3.Connection object at 0x107b70770>
Traceback (most recent call last):
  File "/Library/Python/2.7/site-packages/SQLAlchemy-0.9.8-py2.7-macosx-10.10-intel.egg/sqlalchemy/pool.py", line 250, in _close_connection
    self._dialect.do_close(connection)
  File "/Library/Python/2.7/site-packages/SQLAlchemy-0.9.8-py2.7-macosx-10.10-intel.egg/sqlalchemy/engine/default.py", line 412, in do_close
    dbapi_connection.close()
ProgrammingError: SQLite objects created in a thread can only be used in that same thread.The object was created in thread id 4443869184 and this is thread id 140735276184320
2014-12-29 15:49:48,063 pool _finalize_fairy 574 : Exception during reset or similar
Traceback (most recent call last):
  File "/Library/Python/2.7/site-packages/SQLAlchemy-0.9.8-py2.7-macosx-10.10-intel.egg/sqlalchemy/pool.py", line 567, in _finalize_fairy
    fairy._reset(pool)
  File "/Library/Python/2.7/site-packages/SQLAlchemy-0.9.8-py2.7-macosx-10.10-intel.egg/sqlalchemy/pool.py", line 701, in _reset
    pool._dialect.do_rollback(self)
  File "/Library/Python/2.7/site-packages/SQLAlchemy-0.9.8-py2.7-macosx-10.10-intel.egg/sqlalchemy/engine/default.py", line 406, in do_rollback
    dbapi_connection.rollback()
ProgrammingError: SQLite objects created in a thread can only be used in that same thread.The object was created in thread id 4336914432 and this is thread id 140735276184320
2014-12-29 15:49:48,067 pool _close_connection 255 : Exception closing connection <sqlite3.Connection object at 0x101722770>
Traceback (most recent call last):
  File "/Library/Python/2.7/site-packages/SQLAlchemy-0.9.8-py2.7-macosx-10.10-intel.egg/sqlalchemy/pool.py", line 250, in _close_connection
    self._dialect.do_close(connection)
  File "/Library/Python/2.7/site-packages/SQLAlchemy-0.9.8-py2.7-macosx-10.10-intel.egg/sqlalchemy/engine/default.py", line 412, in do_close
    dbapi_connection.close()
ProgrammingError: SQLite objects created in a thread can only be used in that same thread.The object was created in thread id 4336914432 and this is thread id 140735276184320
2014-12-29 17:12:24,158 pool _finalize_fairy 574 : Exception during reset or similar
Traceback (most recent call last):
  File "/Library/Python/2.7/site-packages/SQLAlchemy-0.9.8-py2.7-macosx-10.10-intel.egg/sqlalchemy/pool.py", line 567, in _finalize_fairy
    fairy._reset(pool)
  File "/Library/Python/2.7/site-packages/SQLAlchemy-0.9.8-py2.7-macosx-10.10-intel.egg/sqlalchemy/pool.py", line 701, in _reset
    pool._dialect.do_rollback(self)
  File "/Library/Python/2.7/site-packages/SQLAlchemy-0.9.8-py2.7-macosx-10.10-intel.egg/sqlalchemy/engine/default.py", line 406, in do_rollback
    dbapi_connection.rollback()
ProgrammingError: SQLite objects created in a thread can only be used in that same thread.The object was created in thread id 4456452096 and this is thread id 140735276184320
2014-12-29 17:12:24,160 pool _close_connection 255 : Exception closing connection <sqlite3.Connection object at 0x108821770>
Traceback (most recent call last):
  File "/Library/Python/2.7/site-packages/SQLAlchemy-0.9.8-py2.7-macosx-10.10-intel.egg/sqlalchemy/pool.py", line 250, in _close_connection
    self._dialect.do_close(connection)
  File "/Library/Python/2.7/site-packages/SQLAlchemy-0.9.8-py2.7-macosx-10.10-intel.egg/sqlalchemy/engine/default.py", line 412, in do_close
    dbapi_connection.close()
ProgrammingError: SQLite objects created in a thread can only be used in that same thread.The object was created in thread id 4456452096 and this is thread id 140735276184320
2014-12-29 20:17:07,605 pool _finalize_fairy 574 : Exception during reset or similar
Traceback (most recent call last):
  File "/Library/Python/2.7/site-packages/SQLAlchemy-0.9.8-py2.7-macosx-10.10-intel.egg/sqlalchemy/pool.py", line 567, in _finalize_fairy
    fairy._reset(pool)
  File "/Library/Python/2.7/site-packages/SQLAlchemy-0.9.8-py2.7-macosx-10.10-intel.egg/sqlalchemy/pool.py", line 701, in _reset
    pool._dialect.do_rollback(self)
  File "/Library/Python/2.7/site-packages/SQLAlchemy-0.9.8-py2.7-macosx-10.10-intel.egg/sqlalchemy/engine/default.py", line 406, in do_rollback
    dbapi_connection.rollback()
ProgrammingError: SQLite objects created in a thread can only be used in that same thread.The object was created in thread id 4418703360 and this is thread id 140735276184320
2014-12-29 20:17:07,612 pool _close_connection 255 : Exception closing connection <sqlite3.Connection object at 0x1064a5770>
Traceback (most recent call last):
  File "/Library/Python/2.7/site-packages/SQLAlchemy-0.9.8-py2.7-macosx-10.10-intel.egg/sqlalchemy/pool.py", line 250, in _close_connection
    self._dialect.do_close(connection)
  File "/Library/Python/2.7/site-packages/SQLAlchemy-0.9.8-py2.7-macosx-10.10-intel.egg/sqlalchemy/engine/default.py", line 412, in do_close
    dbapi_connection.close()
ProgrammingError: SQLite objects created in a thread can only be used in that same thread.The object was created in thread id 4418703360 and this is thread id 140735276184320
2014-12-31 09:39:43,222 pool _finalize_fairy 574 : Exception during reset or similar
Traceback (most recent call last):
  File "/Library/Python/2.7/site-packages/SQLAlchemy-0.9.8-py2.7-macosx-10.10-intel.egg/sqlalchemy/pool.py", line 567, in _finalize_fairy
    fairy._reset(pool)
  File "/Library/Python/2.7/site-packages/SQLAlchemy-0.9.8-py2.7-macosx-10.10-intel.egg/sqlalchemy/pool.py", line 701, in _reset
    pool._dialect.do_rollback(self)
  File "/Library/Python/2.7/site-packages/SQLAlchemy-0.9.8-py2.7-macosx-10.10-intel.egg/sqlalchemy/engine/default.py", line 406, in do_rollback
    dbapi_connection.rollback()
ProgrammingError: SQLite objects created in a thread can only be used in that same thread.The object was created in thread id 4399828992 and this is thread id 140735288210176
2014-12-31 09:39:43,229 pool _close_connection 255 : Exception closing connection <sqlite3.Connection object at 0x105264770>
Traceback (most recent call last):
  File "/Library/Python/2.7/site-packages/SQLAlchemy-0.9.8-py2.7-macosx-10.10-intel.egg/sqlalchemy/pool.py", line 250, in _close_connection
    self._dialect.do_close(connection)
  File "/Library/Python/2.7/site-packages/SQLAlchemy-0.9.8-py2.7-macosx-10.10-intel.egg/sqlalchemy/engine/default.py", line 412, in do_close
    dbapi_connection.close()
ProgrammingError: SQLite objects created in a thread can only be used in that same thread.The object was created in thread id 4399828992 and this is thread id 140735288210176
2015-01-02 12:54:42,336 pool _finalize_fairy 574 : Exception during reset or similar
Traceback (most recent call last):
  File "/Library/Python/2.7/site-packages/SQLAlchemy-0.9.8-py2.7-macosx-10.10-intel.egg/sqlalchemy/pool.py", line 567, in _finalize_fairy
    fairy._reset(pool)
  File "/Library/Python/2.7/site-packages/SQLAlchemy-0.9.8-py2.7-macosx-10.10-intel.egg/sqlalchemy/pool.py", line 701, in _reset
    pool._dialect.do_rollback(self)
  File "/Library/Python/2.7/site-packages/SQLAlchemy-0.9.8-py2.7-macosx-10.10-intel.egg/sqlalchemy/engine/default.py", line 406, in do_rollback
    dbapi_connection.rollback()
ProgrammingError: SQLite objects created in a thread can only be used in that same thread.The object was created in thread id 4555018240 and this is thread id 140735191778048
2015-01-02 12:54:42,341 pool _close_connection 255 : Exception closing connection <sqlite3.Connection object at 0x10e57f770>
Traceback (most recent call last):
  File "/Library/Python/2.7/site-packages/SQLAlchemy-0.9.8-py2.7-macosx-10.10-intel.egg/sqlalchemy/pool.py", line 250, in _close_connection
    self._dialect.do_close(connection)
  File "/Library/Python/2.7/site-packages/SQLAlchemy-0.9.8-py2.7-macosx-10.10-intel.egg/sqlalchemy/engine/default.py", line 412, in do_close
    dbapi_connection.close()
ProgrammingError: SQLite objects created in a thread can only be used in that same thread.The object was created in thread id 4555018240 and this is thread id 140735191778048
2015-01-05 14:30:10,185 pool _finalize_fairy 574 : Exception during reset or similar
Traceback (most recent call last):
  File "/Library/Python/2.7/site-packages/SQLAlchemy-0.9.8-py2.7-macosx-10.10-intel.egg/sqlalchemy/pool.py", line 567, in _finalize_fairy
    fairy._reset(pool)
  File "/Library/Python/2.7/site-packages/SQLAlchemy-0.9.8-py2.7-macosx-10.10-intel.egg/sqlalchemy/pool.py", line 701, in _reset
    pool._dialect.do_rollback(self)
  File "/Library/Python/2.7/site-packages/SQLAlchemy-0.9.8-py2.7-macosx-10.10-intel.egg/sqlalchemy/engine/default.py", line 406, in do_rollback
    dbapi_connection.rollback()
ProgrammingError: SQLite objects created in a thread can only be used in that same thread.The object was created in thread id 4525789184 and this is thread id 140735191778048
2015-01-05 14:30:10,192 pool _close_connection 255 : Exception closing connection <sqlite3.Connection object at 0x10cb42770>
Traceback (most recent call last):
  File "/Library/Python/2.7/site-packages/SQLAlchemy-0.9.8-py2.7-macosx-10.10-intel.egg/sqlalchemy/pool.py", line 250, in _close_connection
    self._dialect.do_close(connection)
  File "/Library/Python/2.7/site-packages/SQLAlchemy-0.9.8-py2.7-macosx-10.10-intel.egg/sqlalchemy/engine/default.py", line 412, in do_close
    dbapi_connection.close()
ProgrammingError: SQLite objects created in a thread can only be used in that same thread.The object was created in thread id 4525789184 and this is thread id 140735191778048
2015-01-07 10:30:56,877 pool _finalize_fairy 574 : Exception during reset or similar
Traceback (most recent call last):
  File "/Library/Python/2.7/site-packages/SQLAlchemy-0.9.8-py2.7-macosx-10.10-intel.egg/sqlalchemy/pool.py", line 567, in _finalize_fairy
    fairy._reset(pool)
  File "/Library/Python/2.7/site-packages/SQLAlchemy-0.9.8-py2.7-macosx-10.10-intel.egg/sqlalchemy/pool.py", line 701, in _reset
    pool._dialect.do_rollback(self)
  File "/Library/Python/2.7/site-packages/SQLAlchemy-0.9.8-py2.7-macosx-10.10-intel.egg/sqlalchemy/engine/default.py", line 406, in do_rollback
    dbapi_connection.rollback()
ProgrammingError: SQLite objects created in a thread can only be used in that same thread.The object was created in thread id 4366274560 and this is thread id 140735191778048
2015-01-07 10:30:56,883 pool _close_connection 255 : Exception closing connection <sqlite3.Connection object at 0x1031b8770>
Traceback (most recent call last):
  File "/Library/Python/2.7/site-packages/SQLAlchemy-0.9.8-py2.7-macosx-10.10-intel.egg/sqlalchemy/pool.py", line 250, in _close_connection
    self._dialect.do_close(connection)
  File "/Library/Python/2.7/site-packages/SQLAlchemy-0.9.8-py2.7-macosx-10.10-intel.egg/sqlalchemy/engine/default.py", line 412, in do_close
    dbapi_connection.close()
ProgrammingError: SQLite objects created in a thread can only be used in that same thread.The object was created in thread id 4366274560 and this is thread id 140735191778048
2015-01-07 10:30:57,754 pool _finalize_fairy 574 : Exception during reset or similar
Traceback (most recent call last):
  File "/Library/Python/2.7/site-packages/SQLAlchemy-0.9.8-py2.7-macosx-10.10-intel.egg/sqlalchemy/pool.py", line 567, in _finalize_fairy
    fairy._reset(pool)
  File "/Library/Python/2.7/site-packages/SQLAlchemy-0.9.8-py2.7-macosx-10.10-intel.egg/sqlalchemy/pool.py", line 701, in _reset
    pool._dialect.do_rollback(self)
  File "/Library/Python/2.7/site-packages/SQLAlchemy-0.9.8-py2.7-macosx-10.10-intel.egg/sqlalchemy/engine/default.py", line 406, in do_rollback
    dbapi_connection.rollback()
ProgrammingError: SQLite objects created in a thread can only be used in that same thread.The object was created in thread id 4456452096 and this is thread id 140735191778048
2015-01-07 10:30:57,756 pool _close_connection 255 : Exception closing connection <sqlite3.Connection object at 0x1088b8770>
Traceback (most recent call last):
  File "/Library/Python/2.7/site-packages/SQLAlchemy-0.9.8-py2.7-macosx-10.10-intel.egg/sqlalchemy/pool.py", line 250, in _close_connection
    self._dialect.do_close(connection)
  File "/Library/Python/2.7/site-packages/SQLAlchemy-0.9.8-py2.7-macosx-10.10-intel.egg/sqlalchemy/engine/default.py", line 412, in do_close
    dbapi_connection.close()
ProgrammingError: SQLite objects created in a thread can only be used in that same thread.The object was created in thread id 4456452096 and this is thread id 140735191778048
2015-01-12 09:44:42,638 pool _finalize_fairy 574 : Exception during reset or similar
Traceback (most recent call last):
  File "/Library/Python/2.7/site-packages/SQLAlchemy-0.9.8-py2.7-macosx-10.10-intel.egg/sqlalchemy/pool.py", line 567, in _finalize_fairy
    fairy._reset(pool)
  File "/Library/Python/2.7/site-packages/SQLAlchemy-0.9.8-py2.7-macosx-10.10-intel.egg/sqlalchemy/pool.py", line 701, in _reset
    pool._dialect.do_rollback(self)
  File "/Library/Python/2.7/site-packages/SQLAlchemy-0.9.8-py2.7-macosx-10.10-intel.egg/sqlalchemy/engine/default.py", line 406, in do_rollback
    dbapi_connection.rollback()
ProgrammingError: SQLite objects created in a thread can only be used in that same thread.The object was created in thread id 4397731840 and this is thread id 140735191778048
2015-01-12 09:44:42,644 pool _close_connection 255 : Exception closing connection <sqlite3.Connection object at 0x10508e770>
Traceback (most recent call last):
  File "/Library/Python/2.7/site-packages/SQLAlchemy-0.9.8-py2.7-macosx-10.10-intel.egg/sqlalchemy/pool.py", line 250, in _close_connection
    self._dialect.do_close(connection)
  File "/Library/Python/2.7/site-packages/SQLAlchemy-0.9.8-py2.7-macosx-10.10-intel.egg/sqlalchemy/engine/default.py", line 412, in do_close
    dbapi_connection.close()
ProgrammingError: SQLite objects created in a thread can only be used in that same thread.The object was created in thread id 4397731840 and this is thread id 140735191778048
2015-01-12 09:55:58,297 pool _finalize_fairy 574 : Exception during reset or similar
Traceback (most recent call last):
  File "/Library/Python/2.7/site-packages/SQLAlchemy-0.9.8-py2.7-macosx-10.10-intel.egg/sqlalchemy/pool.py", line 567, in _finalize_fairy
    fairy._reset(pool)
  File "/Library/Python/2.7/site-packages/SQLAlchemy-0.9.8-py2.7-macosx-10.10-intel.egg/sqlalchemy/pool.py", line 701, in _reset
    pool._dialect.do_rollback(self)
  File "/Library/Python/2.7/site-packages/SQLAlchemy-0.9.8-py2.7-macosx-10.10-intel.egg/sqlalchemy/engine/default.py", line 406, in do_rollback
    dbapi_connection.rollback()
ProgrammingError: SQLite objects created in a thread can only be used in that same thread.The object was created in thread id 4466937856 and this is thread id 140735191778048
2015-01-12 09:55:58,298 pool _close_connection 255 : Exception closing connection <sqlite3.Connection object at 0x109186770>
Traceback (most recent call last):
  File "/Library/Python/2.7/site-packages/SQLAlchemy-0.9.8-py2.7-macosx-10.10-intel.egg/sqlalchemy/pool.py", line 250, in _close_connection
    self._dialect.do_close(connection)
  File "/Library/Python/2.7/site-packages/SQLAlchemy-0.9.8-py2.7-macosx-10.10-intel.egg/sqlalchemy/engine/default.py", line 412, in do_close
    dbapi_connection.close()
ProgrammingError: SQLite objects created in a thread can only be used in that same thread.The object was created in thread id 4466937856 and this is thread id 140735191778048
2015-01-12 15:09:13,730 pool _finalize_fairy 574 : Exception during reset or similar
Traceback (most recent call last):
  File "/Library/Python/2.7/site-packages/SQLAlchemy-0.9.8-py2.7-macosx-10.10-intel.egg/sqlalchemy/pool.py", line 567, in _finalize_fairy
    fairy._reset(pool)
  File "/Library/Python/2.7/site-packages/SQLAlchemy-0.9.8-py2.7-macosx-10.10-intel.egg/sqlalchemy/pool.py", line 701, in _reset
    pool._dialect.do_rollback(self)
  File "/Library/Python/2.7/site-packages/SQLAlchemy-0.9.8-py2.7-macosx-10.10-intel.egg/sqlalchemy/engine/default.py", line 406, in do_rollback
    dbapi_connection.rollback()
ProgrammingError: SQLite objects created in a thread can only be used in that same thread.The object was created in thread id 4504686592 and this is thread id 140735191778048
2015-01-12 15:09:13,733 pool _close_connection 255 : Exception closing connection <sqlite3.Connection object at 0x10b634770>
Traceback (most recent call last):
  File "/Library/Python/2.7/site-packages/SQLAlchemy-0.9.8-py2.7-macosx-10.10-intel.egg/sqlalchemy/pool.py", line 250, in _close_connection
    self._dialect.do_close(connection)
  File "/Library/Python/2.7/site-packages/SQLAlchemy-0.9.8-py2.7-macosx-10.10-intel.egg/sqlalchemy/engine/default.py", line 412, in do_close
    dbapi_connection.close()
ProgrammingError: SQLite objects created in a thread can only be used in that same thread.The object was created in thread id 4504686592 and this is thread id 140735191778048
2015-01-12 16:35:50,789 pool _finalize_fairy 574 : Exception during reset or similar
Traceback (most recent call last):
  File "/Library/Python/2.7/site-packages/SQLAlchemy-0.9.8-py2.7-macosx-10.10-intel.egg/sqlalchemy/pool.py", line 567, in _finalize_fairy
    fairy._reset(pool)
  File "/Library/Python/2.7/site-packages/SQLAlchemy-0.9.8-py2.7-macosx-10.10-intel.egg/sqlalchemy/pool.py", line 701, in _reset
    pool._dialect.do_rollback(self)
  File "/Library/Python/2.7/site-packages/SQLAlchemy-0.9.8-py2.7-macosx-10.10-intel.egg/sqlalchemy/engine/default.py", line 406, in do_rollback
    dbapi_connection.rollback()
ProgrammingError: SQLite objects created in a thread can only be used in that same thread.The object was created in thread id 4552921088 and this is thread id 140735191778048
2015-01-12 16:35:50,794 pool _close_connection 255 : Exception closing connection <sqlite3.Connection object at 0x10e416770>
Traceback (most recent call last):
  File "/Library/Python/2.7/site-packages/SQLAlchemy-0.9.8-py2.7-macosx-10.10-intel.egg/sqlalchemy/pool.py", line 250, in _close_connection
    self._dialect.do_close(connection)
  File "/Library/Python/2.7/site-packages/SQLAlchemy-0.9.8-py2.7-macosx-10.10-intel.egg/sqlalchemy/engine/default.py", line 412, in do_close
    dbapi_connection.close()
ProgrammingError: SQLite objects created in a thread can only be used in that same thread.The object was created in thread id 4552921088 and this is thread id 140735191778048
2015-01-13 11:23:57,996 pool _finalize_fairy 574 : Exception during reset or similar
Traceback (most recent call last):
  File "/Library/Python/2.7/site-packages/SQLAlchemy-0.9.8-py2.7-macosx-10.10-intel.egg/sqlalchemy/pool.py", line 567, in _finalize_fairy
    fairy._reset(pool)
  File "/Library/Python/2.7/site-packages/SQLAlchemy-0.9.8-py2.7-macosx-10.10-intel.egg/sqlalchemy/pool.py", line 701, in _reset
    pool._dialect.do_rollback(self)
  File "/Library/Python/2.7/site-packages/SQLAlchemy-0.9.8-py2.7-macosx-10.10-intel.egg/sqlalchemy/engine/default.py", line 406, in do_rollback
    dbapi_connection.rollback()
ProgrammingError: SQLite objects created in a thread can only be used in that same thread.The object was created in thread id 4424994816 and this is thread id 140735191778048
2015-01-13 11:23:58,000 pool _close_connection 255 : Exception closing connection <sqlite3.Connection object at 0x106ac0770>
Traceback (most recent call last):
  File "/Library/Python/2.7/site-packages/SQLAlchemy-0.9.8-py2.7-macosx-10.10-intel.egg/sqlalchemy/pool.py", line 250, in _close_connection
    self._dialect.do_close(connection)
  File "/Library/Python/2.7/site-packages/SQLAlchemy-0.9.8-py2.7-macosx-10.10-intel.egg/sqlalchemy/engine/default.py", line 412, in do_close
    dbapi_connection.close()
ProgrammingError: SQLite objects created in a thread can only be used in that same thread.The object was created in thread id 4424994816 and this is thread id 140735191778048
2015-01-13 20:04:36,745 pool _finalize_fairy 574 : Exception during reset or similar
Traceback (most recent call last):
  File "/Library/Python/2.7/site-packages/SQLAlchemy-0.9.8-py2.7-macosx-10.10-intel.egg/sqlalchemy/pool.py", line 567, in _finalize_fairy
    fairy._reset(pool)
  File "/Library/Python/2.7/site-packages/SQLAlchemy-0.9.8-py2.7-macosx-10.10-intel.egg/sqlalchemy/pool.py", line 701, in _reset
    pool._dialect.do_rollback(self)
  File "/Library/Python/2.7/site-packages/SQLAlchemy-0.9.8-py2.7-macosx-10.10-intel.egg/sqlalchemy/engine/default.py", line 406, in do_rollback
    dbapi_connection.rollback()
ProgrammingError: SQLite objects created in a thread can only be used in that same thread.The object was created in thread id 4383051776 and this is thread id 140735191192320
2015-01-13 20:04:36,749 pool _close_connection 255 : Exception closing connection <sqlite3.Connection object at 0x1042a2770>
Traceback (most recent call last):
  File "/Library/Python/2.7/site-packages/SQLAlchemy-0.9.8-py2.7-macosx-10.10-intel.egg/sqlalchemy/pool.py", line 250, in _close_connection
    self._dialect.do_close(connection)
  File "/Library/Python/2.7/site-packages/SQLAlchemy-0.9.8-py2.7-macosx-10.10-intel.egg/sqlalchemy/engine/default.py", line 412, in do_close
    dbapi_connection.close()
ProgrammingError: SQLite objects created in a thread can only be used in that same thread.The object was created in thread id 4383051776 and this is thread id 140735191192320
2015-01-14 09:56:05,241 pool _finalize_fairy 574 : Exception during reset or similar
Traceback (most recent call last):
  File "/Library/Python/2.7/site-packages/SQLAlchemy-0.9.8-py2.7-macosx-10.10-intel.egg/sqlalchemy/pool.py", line 567, in _finalize_fairy
    fairy._reset(pool)
  File "/Library/Python/2.7/site-packages/SQLAlchemy-0.9.8-py2.7-macosx-10.10-intel.egg/sqlalchemy/pool.py", line 701, in _reset
    pool._dialect.do_rollback(self)
  File "/Library/Python/2.7/site-packages/SQLAlchemy-0.9.8-py2.7-macosx-10.10-intel.egg/sqlalchemy/engine/default.py", line 406, in do_rollback
    dbapi_connection.rollback()
ProgrammingError: SQLite objects created in a thread can only be used in that same thread.The object was created in thread id 4362080256 and this is thread id 140735191192320
2015-01-14 09:56:05,244 pool _close_connection 255 : Exception closing connection <sqlite3.Connection object at 0x102eaa770>
Traceback (most recent call last):
  File "/Library/Python/2.7/site-packages/SQLAlchemy-0.9.8-py2.7-macosx-10.10-intel.egg/sqlalchemy/pool.py", line 250, in _close_connection
    self._dialect.do_close(connection)
  File "/Library/Python/2.7/site-packages/SQLAlchemy-0.9.8-py2.7-macosx-10.10-intel.egg/sqlalchemy/engine/default.py", line 412, in do_close
    dbapi_connection.close()
ProgrammingError: SQLite objects created in a thread can only be used in that same thread.The object was created in thread id 4362080256 and this is thread id 140735191192320
2015-01-14 10:21:59,470 pool _finalize_fairy 574 : Exception during reset or similar
Traceback (most recent call last):
  File "/Library/Python/2.7/site-packages/SQLAlchemy-0.9.8-py2.7-macosx-10.10-intel.egg/sqlalchemy/pool.py", line 567, in _finalize_fairy
    fairy._reset(pool)
  File "/Library/Python/2.7/site-packages/SQLAlchemy-0.9.8-py2.7-macosx-10.10-intel.egg/sqlalchemy/pool.py", line 701, in _reset
    pool._dialect.do_rollback(self)
  File "/Library/Python/2.7/site-packages/SQLAlchemy-0.9.8-py2.7-macosx-10.10-intel.egg/sqlalchemy/engine/default.py", line 406, in do_rollback
    dbapi_connection.rollback()
ProgrammingError: SQLite objects created in a thread can only be used in that same thread.The object was created in thread id 4397731840 and this is thread id 140735191192320
2015-01-14 10:21:59,474 pool _close_connection 255 : Exception closing connection <sqlite3.Connection object at 0x104f58770>
Traceback (most recent call last):
  File "/Library/Python/2.7/site-packages/SQLAlchemy-0.9.8-py2.7-macosx-10.10-intel.egg/sqlalchemy/pool.py", line 250, in _close_connection
    self._dialect.do_close(connection)
  File "/Library/Python/2.7/site-packages/SQLAlchemy-0.9.8-py2.7-macosx-10.10-intel.egg/sqlalchemy/engine/default.py", line 412, in do_close
    dbapi_connection.close()
ProgrammingError: SQLite objects created in a thread can only be used in that same thread.The object was created in thread id 4397731840 and this is thread id 140735191192320
2015-01-14 10:24:28,125 pool _finalize_fairy 574 : Exception during reset or similar
Traceback (most recent call last):
  File "/Library/Python/2.7/site-packages/SQLAlchemy-0.9.8-py2.7-macosx-10.10-intel.egg/sqlalchemy/pool.py", line 567, in _finalize_fairy
    fairy._reset(pool)
  File "/Library/Python/2.7/site-packages/SQLAlchemy-0.9.8-py2.7-macosx-10.10-intel.egg/sqlalchemy/pool.py", line 701, in _reset
    pool._dialect.do_rollback(self)
  File "/Library/Python/2.7/site-packages/SQLAlchemy-0.9.8-py2.7-macosx-10.10-intel.egg/sqlalchemy/engine/default.py", line 406, in do_rollback
    dbapi_connection.rollback()
ProgrammingError: SQLite objects created in a thread can only be used in that same thread.The object was created in thread id 4504686592 and this is thread id 140735191192320
2015-01-14 10:24:28,126 pool _close_connection 255 : Exception closing connection <sqlite3.Connection object at 0x10b687770>
Traceback (most recent call last):
  File "/Library/Python/2.7/site-packages/SQLAlchemy-0.9.8-py2.7-macosx-10.10-intel.egg/sqlalchemy/pool.py", line 250, in _close_connection
    self._dialect.do_close(connection)
  File "/Library/Python/2.7/site-packages/SQLAlchemy-0.9.8-py2.7-macosx-10.10-intel.egg/sqlalchemy/engine/default.py", line 412, in do_close
    dbapi_connection.close()
ProgrammingError: SQLite objects created in a thread can only be used in that same thread.The object was created in thread id 4504686592 and this is thread id 140735191192320
2015-01-14 12:32:39,958 pool _finalize_fairy 574 : Exception during reset or similar
Traceback (most recent call last):
  File "/Library/Python/2.7/site-packages/SQLAlchemy-0.9.8-py2.7-macosx-10.10-intel.egg/sqlalchemy/pool.py", line 567, in _finalize_fairy
    fairy._reset(pool)
  File "/Library/Python/2.7/site-packages/SQLAlchemy-0.9.8-py2.7-macosx-10.10-intel.egg/sqlalchemy/pool.py", line 701, in _reset
    pool._dialect.do_rollback(self)
  File "/Library/Python/2.7/site-packages/SQLAlchemy-0.9.8-py2.7-macosx-10.10-intel.egg/sqlalchemy/engine/default.py", line 406, in do_rollback
    dbapi_connection.rollback()
ProgrammingError: SQLite objects created in a thread can only be used in that same thread.The object was created in thread id 4546760704 and this is thread id 140735191192320
2015-01-14 12:32:39,964 pool _close_connection 255 : Exception closing connection <sqlite3.Connection object at 0x10df38770>
Traceback (most recent call last):
  File "/Library/Python/2.7/site-packages/SQLAlchemy-0.9.8-py2.7-macosx-10.10-intel.egg/sqlalchemy/pool.py", line 250, in _close_connection
    self._dialect.do_close(connection)
  File "/Library/Python/2.7/site-packages/SQLAlchemy-0.9.8-py2.7-macosx-10.10-intel.egg/sqlalchemy/engine/default.py", line 412, in do_close
    dbapi_connection.close()
ProgrammingError: SQLite objects created in a thread can only be used in that same thread.The object was created in thread id 4546760704 and this is thread id 140735191192320
2015-01-14 13:50:34,684 pool _finalize_fairy 574 : Exception during reset or similar
Traceback (most recent call last):
  File "/Library/Python/2.7/site-packages/SQLAlchemy-0.9.8-py2.7-macosx-10.10-intel.egg/sqlalchemy/pool.py", line 567, in _finalize_fairy
    fairy._reset(pool)
  File "/Library/Python/2.7/site-packages/SQLAlchemy-0.9.8-py2.7-macosx-10.10-intel.egg/sqlalchemy/pool.py", line 701, in _reset
    pool._dialect.do_rollback(self)
  File "/Library/Python/2.7/site-packages/SQLAlchemy-0.9.8-py2.7-macosx-10.10-intel.egg/sqlalchemy/engine/default.py", line 406, in do_rollback
    dbapi_connection.rollback()
ProgrammingError: SQLite objects created in a thread can only be used in that same thread.The object was created in thread id 4355788800 and this is thread id 140735191192320
2015-01-14 13:50:34,687 pool _close_connection 255 : Exception closing connection <sqlite3.Connection object at 0x102893770>
Traceback (most recent call last):
  File "/Library/Python/2.7/site-packages/SQLAlchemy-0.9.8-py2.7-macosx-10.10-intel.egg/sqlalchemy/pool.py", line 250, in _close_connection
    self._dialect.do_close(connection)
  File "/Library/Python/2.7/site-packages/SQLAlchemy-0.9.8-py2.7-macosx-10.10-intel.egg/sqlalchemy/engine/default.py", line 412, in do_close
    dbapi_connection.close()
ProgrammingError: SQLite objects created in a thread can only be used in that same thread.The object was created in thread id 4355788800 and this is thread id 140735191192320
2015-01-14 14:15:36,646 pool _finalize_fairy 574 : Exception during reset or similar
Traceback (most recent call last):
  File "/Library/Python/2.7/site-packages/SQLAlchemy-0.9.8-py2.7-macosx-10.10-intel.egg/sqlalchemy/pool.py", line 567, in _finalize_fairy
    fairy._reset(pool)
  File "/Library/Python/2.7/site-packages/SQLAlchemy-0.9.8-py2.7-macosx-10.10-intel.egg/sqlalchemy/pool.py", line 701, in _reset
    pool._dialect.do_rollback(self)
  File "/Library/Python/2.7/site-packages/SQLAlchemy-0.9.8-py2.7-macosx-10.10-intel.egg/sqlalchemy/engine/default.py", line 406, in do_rollback
    dbapi_connection.rollback()
ProgrammingError: SQLite objects created in a thread can only be used in that same thread.The object was created in thread id 4538241024 and this is thread id 140735191192320
2015-01-14 14:15:36,650 pool _close_connection 255 : Exception closing connection <sqlite3.Connection object at 0x10d5f2770>
Traceback (most recent call last):
  File "/Library/Python/2.7/site-packages/SQLAlchemy-0.9.8-py2.7-macosx-10.10-intel.egg/sqlalchemy/pool.py", line 250, in _close_connection
    self._dialect.do_close(connection)
  File "/Library/Python/2.7/site-packages/SQLAlchemy-0.9.8-py2.7-macosx-10.10-intel.egg/sqlalchemy/engine/default.py", line 412, in do_close
    dbapi_connection.close()
ProgrammingError: SQLite objects created in a thread can only be used in that same thread.The object was created in thread id 4538241024 and this is thread id 140735191192320
2015-01-14 14:20:20,874 pool _finalize_fairy 574 : Exception during reset or similar
Traceback (most recent call last):
  File "/Library/Python/2.7/site-packages/SQLAlchemy-0.9.8-py2.7-macosx-10.10-intel.egg/sqlalchemy/pool.py", line 567, in _finalize_fairy
    fairy._reset(pool)
  File "/Library/Python/2.7/site-packages/SQLAlchemy-0.9.8-py2.7-macosx-10.10-intel.egg/sqlalchemy/pool.py", line 701, in _reset
    pool._dialect.do_rollback(self)
  File "/Library/Python/2.7/site-packages/SQLAlchemy-0.9.8-py2.7-macosx-10.10-intel.egg/sqlalchemy/engine/default.py", line 406, in do_rollback
    dbapi_connection.rollback()
ProgrammingError: SQLite objects created in a thread can only be used in that same thread.The object was created in thread id 4441772032 and this is thread id 140735191192320
2015-01-14 14:20:20,875 pool _close_connection 255 : Exception closing connection <sqlite3.Connection object at 0x107a3b770>
Traceback (most recent call last):
  File "/Library/Python/2.7/site-packages/SQLAlchemy-0.9.8-py2.7-macosx-10.10-intel.egg/sqlalchemy/pool.py", line 250, in _close_connection
    self._dialect.do_close(connection)
  File "/Library/Python/2.7/site-packages/SQLAlchemy-0.9.8-py2.7-macosx-10.10-intel.egg/sqlalchemy/engine/default.py", line 412, in do_close
    dbapi_connection.close()
ProgrammingError: SQLite objects created in a thread can only be used in that same thread.The object was created in thread id 4441772032 and this is thread id 140735191192320
2015-01-15 15:30:22,130 pool _finalize_fairy 574 : Exception during reset or similar
Traceback (most recent call last):
  File "/Library/Python/2.7/site-packages/SQLAlchemy-0.9.8-py2.7-macosx-10.10-intel.egg/sqlalchemy/pool.py", line 567, in _finalize_fairy
    fairy._reset(pool)
  File "/Library/Python/2.7/site-packages/SQLAlchemy-0.9.8-py2.7-macosx-10.10-intel.egg/sqlalchemy/pool.py", line 701, in _reset
    pool._dialect.do_rollback(self)
  File "/Library/Python/2.7/site-packages/SQLAlchemy-0.9.8-py2.7-macosx-10.10-intel.egg/sqlalchemy/engine/default.py", line 406, in do_rollback
    dbapi_connection.rollback()
ProgrammingError: SQLite objects created in a thread can only be used in that same thread.The object was created in thread id 4542435328 and this is thread id 140735264629504
2015-01-15 15:30:22,133 pool _close_connection 255 : Exception closing connection <sqlite3.Connection object at 0x10d978770>
Traceback (most recent call last):
  File "/Library/Python/2.7/site-packages/SQLAlchemy-0.9.8-py2.7-macosx-10.10-intel.egg/sqlalchemy/pool.py", line 250, in _close_connection
    self._dialect.do_close(connection)
  File "/Library/Python/2.7/site-packages/SQLAlchemy-0.9.8-py2.7-macosx-10.10-intel.egg/sqlalchemy/engine/default.py", line 412, in do_close
    dbapi_connection.close()
ProgrammingError: SQLite objects created in a thread can only be used in that same thread.The object was created in thread id 4542435328 and this is thread id 140735264629504
2015-01-16 14:54:34,087 pool _finalize_fairy 574 : Exception during reset or similar
Traceback (most recent call last):
  File "/Library/Python/2.7/site-packages/SQLAlchemy-0.9.8-py2.7-macosx-10.10-intel.egg/sqlalchemy/pool.py", line 567, in _finalize_fairy
    fairy._reset(pool)
  File "/Library/Python/2.7/site-packages/SQLAlchemy-0.9.8-py2.7-macosx-10.10-intel.egg/sqlalchemy/pool.py", line 701, in _reset
    pool._dialect.do_rollback(self)
  File "/Library/Python/2.7/site-packages/SQLAlchemy-0.9.8-py2.7-macosx-10.10-intel.egg/sqlalchemy/engine/default.py", line 406, in do_rollback
    dbapi_connection.rollback()
ProgrammingError: SQLite objects created in a thread can only be used in that same thread.The object was created in thread id 4515172352 and this is thread id 140735264629504
2015-01-16 14:54:34,092 pool _close_connection 255 : Exception closing connection <sqlite3.Connection object at 0x10c0d6770>
Traceback (most recent call last):
  File "/Library/Python/2.7/site-packages/SQLAlchemy-0.9.8-py2.7-macosx-10.10-intel.egg/sqlalchemy/pool.py", line 250, in _close_connection
    self._dialect.do_close(connection)
  File "/Library/Python/2.7/site-packages/SQLAlchemy-0.9.8-py2.7-macosx-10.10-intel.egg/sqlalchemy/engine/default.py", line 412, in do_close
    dbapi_connection.close()
ProgrammingError: SQLite objects created in a thread can only be used in that same thread.The object was created in thread id 4515172352 and this is thread id 140735264629504
2015-01-19 09:53:09,658 pool _finalize_fairy 574 : Exception during reset or similar
Traceback (most recent call last):
  File "/Library/Python/2.7/site-packages/SQLAlchemy-0.9.8-py2.7-macosx-10.10-intel.egg/sqlalchemy/pool.py", line 567, in _finalize_fairy
    fairy._reset(pool)
  File "/Library/Python/2.7/site-packages/SQLAlchemy-0.9.8-py2.7-macosx-10.10-intel.egg/sqlalchemy/pool.py", line 701, in _reset
    pool._dialect.do_rollback(self)
  File "/Library/Python/2.7/site-packages/SQLAlchemy-0.9.8-py2.7-macosx-10.10-intel.egg/sqlalchemy/engine/default.py", line 406, in do_rollback
    dbapi_connection.rollback()
ProgrammingError: SQLite objects created in a thread can only be used in that same thread.The object was created in thread id 4508880896 and this is thread id 140735288509184
2015-01-19 09:53:09,662 pool _close_connection 255 : Exception closing connection <sqlite3.Connection object at 0x10ba08770>
Traceback (most recent call last):
  File "/Library/Python/2.7/site-packages/SQLAlchemy-0.9.8-py2.7-macosx-10.10-intel.egg/sqlalchemy/pool.py", line 250, in _close_connection
    self._dialect.do_close(connection)
  File "/Library/Python/2.7/site-packages/SQLAlchemy-0.9.8-py2.7-macosx-10.10-intel.egg/sqlalchemy/engine/default.py", line 412, in do_close
    dbapi_connection.close()
ProgrammingError: SQLite objects created in a thread can only be used in that same thread.The object was created in thread id 4508880896 and this is thread id 140735288509184
2015-01-19 13:43:48,952 pool _finalize_fairy 574 : Exception during reset or similar
Traceback (most recent call last):
  File "/Library/Python/2.7/site-packages/SQLAlchemy-0.9.8-py2.7-macosx-10.10-intel.egg/sqlalchemy/pool.py", line 567, in _finalize_fairy
    fairy._reset(pool)
  File "/Library/Python/2.7/site-packages/SQLAlchemy-0.9.8-py2.7-macosx-10.10-intel.egg/sqlalchemy/pool.py", line 701, in _reset
    pool._dialect.do_rollback(self)
  File "/Library/Python/2.7/site-packages/SQLAlchemy-0.9.8-py2.7-macosx-10.10-intel.egg/sqlalchemy/engine/default.py", line 406, in do_rollback
    dbapi_connection.rollback()
ProgrammingError: SQLite objects created in a thread can only be used in that same thread.The object was created in thread id 4401926144 and this is thread id 140735282389760
2015-01-19 13:43:48,957 pool _close_connection 255 : Exception closing connection <sqlite3.Connection object at 0x1054de770>
Traceback (most recent call last):
  File "/Library/Python/2.7/site-packages/SQLAlchemy-0.9.8-py2.7-macosx-10.10-intel.egg/sqlalchemy/pool.py", line 250, in _close_connection
    self._dialect.do_close(connection)
  File "/Library/Python/2.7/site-packages/SQLAlchemy-0.9.8-py2.7-macosx-10.10-intel.egg/sqlalchemy/engine/default.py", line 412, in do_close
    dbapi_connection.close()
ProgrammingError: SQLite objects created in a thread can only be used in that same thread.The object was created in thread id 4401926144 and this is thread id 140735282389760
2015-01-19 17:22:50,602 pool _finalize_fairy 574 : Exception during reset or similar
Traceback (most recent call last):
  File "/Library/Python/2.7/site-packages/SQLAlchemy-0.9.8-py2.7-macosx-10.10-intel.egg/sqlalchemy/pool.py", line 567, in _finalize_fairy
    fairy._reset(pool)
  File "/Library/Python/2.7/site-packages/SQLAlchemy-0.9.8-py2.7-macosx-10.10-intel.egg/sqlalchemy/pool.py", line 701, in _reset
    pool._dialect.do_rollback(self)
  File "/Library/Python/2.7/site-packages/SQLAlchemy-0.9.8-py2.7-macosx-10.10-intel.egg/sqlalchemy/engine/default.py", line 406, in do_rollback
    dbapi_connection.rollback()
ProgrammingError: SQLite objects created in a thread can only be used in that same thread.The object was created in thread id 4339011584 and this is thread id 140735282389760
2015-01-19 17:22:50,606 pool _close_connection 255 : Exception closing connection <sqlite3.Connection object at 0x10189e770>
Traceback (most recent call last):
  File "/Library/Python/2.7/site-packages/SQLAlchemy-0.9.8-py2.7-macosx-10.10-intel.egg/sqlalchemy/pool.py", line 250, in _close_connection
    self._dialect.do_close(connection)
  File "/Library/Python/2.7/site-packages/SQLAlchemy-0.9.8-py2.7-macosx-10.10-intel.egg/sqlalchemy/engine/default.py", line 412, in do_close
    dbapi_connection.close()
ProgrammingError: SQLite objects created in a thread can only be used in that same thread.The object was created in thread id 4339011584 and this is thread id 140735282389760
2015-01-20 14:53:29,478 pool _finalize_fairy 574 : Exception during reset or similar
Traceback (most recent call last):
  File "/Library/Python/2.7/site-packages/SQLAlchemy-0.9.8-py2.7-macosx-10.10-intel.egg/sqlalchemy/pool.py", line 567, in _finalize_fairy
    fairy._reset(pool)
  File "/Library/Python/2.7/site-packages/SQLAlchemy-0.9.8-py2.7-macosx-10.10-intel.egg/sqlalchemy/pool.py", line 701, in _reset
    pool._dialect.do_rollback(self)
  File "/Library/Python/2.7/site-packages/SQLAlchemy-0.9.8-py2.7-macosx-10.10-intel.egg/sqlalchemy/engine/default.py", line 406, in do_rollback
    dbapi_connection.rollback()
ProgrammingError: SQLite objects created in a thread can only be used in that same thread.The object was created in thread id 4357885952 and this is thread id 140735245366016
2015-01-20 14:53:29,482 pool _close_connection 255 : Exception closing connection <sqlite3.Connection object at 0x102a5e770>
Traceback (most recent call last):
  File "/Library/Python/2.7/site-packages/SQLAlchemy-0.9.8-py2.7-macosx-10.10-intel.egg/sqlalchemy/pool.py", line 250, in _close_connection
    self._dialect.do_close(connection)
  File "/Library/Python/2.7/site-packages/SQLAlchemy-0.9.8-py2.7-macosx-10.10-intel.egg/sqlalchemy/engine/default.py", line 412, in do_close
    dbapi_connection.close()
ProgrammingError: SQLite objects created in a thread can only be used in that same thread.The object was created in thread id 4357885952 and this is thread id 140735245366016
2015-01-21 16:29:17,593 pool _finalize_fairy 574 : Exception during reset or similar
Traceback (most recent call last):
  File "/Library/Python/2.7/site-packages/SQLAlchemy-0.9.8-py2.7-macosx-10.10-intel.egg/sqlalchemy/pool.py", line 567, in _finalize_fairy
    fairy._reset(pool)
  File "/Library/Python/2.7/site-packages/SQLAlchemy-0.9.8-py2.7-macosx-10.10-intel.egg/sqlalchemy/pool.py", line 701, in _reset
    pool._dialect.do_rollback(self)
  File "/Library/Python/2.7/site-packages/SQLAlchemy-0.9.8-py2.7-macosx-10.10-intel.egg/sqlalchemy/engine/default.py", line 406, in do_rollback
    dbapi_connection.rollback()
ProgrammingError: SQLite objects created in a thread can only be used in that same thread.The object was created in thread id 4550823936 and this is thread id 140735245366016
2015-01-21 16:29:17,599 pool _close_connection 255 : Exception closing connection <sqlite3.Connection object at 0x10e235770>
Traceback (most recent call last):
  File "/Library/Python/2.7/site-packages/SQLAlchemy-0.9.8-py2.7-macosx-10.10-intel.egg/sqlalchemy/pool.py", line 250, in _close_connection
    self._dialect.do_close(connection)
  File "/Library/Python/2.7/site-packages/SQLAlchemy-0.9.8-py2.7-macosx-10.10-intel.egg/sqlalchemy/engine/default.py", line 412, in do_close
    dbapi_connection.close()
ProgrammingError: SQLite objects created in a thread can only be used in that same thread.The object was created in thread id 4550823936 and this is thread id 140735245366016
2015-01-22 09:19:38,725 pool _finalize_fairy 574 : Exception during reset or similar
Traceback (most recent call last):
  File "/Library/Python/2.7/site-packages/SQLAlchemy-0.9.8-py2.7-macosx-10.10-intel.egg/sqlalchemy/pool.py", line 567, in _finalize_fairy
    fairy._reset(pool)
  File "/Library/Python/2.7/site-packages/SQLAlchemy-0.9.8-py2.7-macosx-10.10-intel.egg/sqlalchemy/pool.py", line 701, in _reset
    pool._dialect.do_rollback(self)
  File "/Library/Python/2.7/site-packages/SQLAlchemy-0.9.8-py2.7-macosx-10.10-intel.egg/sqlalchemy/engine/default.py", line 406, in do_rollback
    dbapi_connection.rollback()
ProgrammingError: SQLite objects created in a thread can only be used in that same thread.The object was created in thread id 4475326464 and this is thread id 140735245366016
2015-01-22 09:19:38,729 pool _close_connection 255 : Exception closing connection <sqlite3.Connection object at 0x109993770>
Traceback (most recent call last):
  File "/Library/Python/2.7/site-packages/SQLAlchemy-0.9.8-py2.7-macosx-10.10-intel.egg/sqlalchemy/pool.py", line 250, in _close_connection
    self._dialect.do_close(connection)
  File "/Library/Python/2.7/site-packages/SQLAlchemy-0.9.8-py2.7-macosx-10.10-intel.egg/sqlalchemy/engine/default.py", line 412, in do_close
    dbapi_connection.close()
ProgrammingError: SQLite objects created in a thread can only be used in that same thread.The object was created in thread id 4475326464 and this is thread id 140735245366016
2015-01-22 11:41:37,485 pool _finalize_fairy 574 : Exception during reset or similar
Traceback (most recent call last):
  File "/Library/Python/2.7/site-packages/SQLAlchemy-0.9.8-py2.7-macosx-10.10-intel.egg/sqlalchemy/pool.py", line 567, in _finalize_fairy
    fairy._reset(pool)
  File "/Library/Python/2.7/site-packages/SQLAlchemy-0.9.8-py2.7-macosx-10.10-intel.egg/sqlalchemy/pool.py", line 701, in _reset
    pool._dialect.do_rollback(self)
  File "/Library/Python/2.7/site-packages/SQLAlchemy-0.9.8-py2.7-macosx-10.10-intel.egg/sqlalchemy/engine/default.py", line 406, in do_rollback
    dbapi_connection.rollback()
ProgrammingError: SQLite objects created in a thread can only be used in that same thread.The object was created in thread id 4410314752 and this is thread id 140735245366016
2015-01-22 11:41:37,490 pool _close_connection 255 : Exception closing connection <sqlite3.Connection object at 0x105c32770>
Traceback (most recent call last):
  File "/Library/Python/2.7/site-packages/SQLAlchemy-0.9.8-py2.7-macosx-10.10-intel.egg/sqlalchemy/pool.py", line 250, in _close_connection
    self._dialect.do_close(connection)
  File "/Library/Python/2.7/site-packages/SQLAlchemy-0.9.8-py2.7-macosx-10.10-intel.egg/sqlalchemy/engine/default.py", line 412, in do_close
    dbapi_connection.close()
ProgrammingError: SQLite objects created in a thread can only be used in that same thread.The object was created in thread id 4410314752 and this is thread id 140735245366016
2015-01-26 11:00:33,908 pool _finalize_fairy 574 : Exception during reset or similar
Traceback (most recent call last):
  File "/Library/Python/2.7/site-packages/SQLAlchemy-0.9.8-py2.7-macosx-10.10-intel.egg/sqlalchemy/pool.py", line 567, in _finalize_fairy
    fairy._reset(pool)
  File "/Library/Python/2.7/site-packages/SQLAlchemy-0.9.8-py2.7-macosx-10.10-intel.egg/sqlalchemy/pool.py", line 701, in _reset
    pool._dialect.do_rollback(self)
  File "/Library/Python/2.7/site-packages/SQLAlchemy-0.9.8-py2.7-macosx-10.10-intel.egg/sqlalchemy/engine/default.py", line 406, in do_rollback
    dbapi_connection.rollback()
ProgrammingError: SQLite objects created in a thread can only be used in that same thread.The object was created in thread id 4424994816 and this is thread id 140735245366016
2015-01-26 11:00:33,911 pool _close_connection 255 : Exception closing connection <sqlite3.Connection object at 0x106ac0770>
Traceback (most recent call last):
  File "/Library/Python/2.7/site-packages/SQLAlchemy-0.9.8-py2.7-macosx-10.10-intel.egg/sqlalchemy/pool.py", line 250, in _close_connection
    self._dialect.do_close(connection)
  File "/Library/Python/2.7/site-packages/SQLAlchemy-0.9.8-py2.7-macosx-10.10-intel.egg/sqlalchemy/engine/default.py", line 412, in do_close
    dbapi_connection.close()
ProgrammingError: SQLite objects created in a thread can only be used in that same thread.The object was created in thread id 4424994816 and this is thread id 140735245366016
2015-02-04 14:54:50,367 pool _finalize_fairy 574 : Exception during reset or similar
Traceback (most recent call last):
  File "/Library/Python/2.7/site-packages/SQLAlchemy-0.9.8-py2.7-macosx-10.10-intel.egg/sqlalchemy/pool.py", line 567, in _finalize_fairy
    fairy._reset(pool)
  File "/Library/Python/2.7/site-packages/SQLAlchemy-0.9.8-py2.7-macosx-10.10-intel.egg/sqlalchemy/pool.py", line 701, in _reset
    pool._dialect.do_rollback(self)
  File "/Library/Python/2.7/site-packages/SQLAlchemy-0.9.8-py2.7-macosx-10.10-intel.egg/sqlalchemy/engine/default.py", line 406, in do_rollback
    dbapi_connection.rollback()
ProgrammingError: SQLite objects created in a thread can only be used in that same thread.The object was created in thread id 4345303040 and this is thread id 140735173817088
2015-02-04 14:54:50,371 pool _close_connection 255 : Exception closing connection <sqlite3.Connection object at 0x101d68770>
Traceback (most recent call last):
  File "/Library/Python/2.7/site-packages/SQLAlchemy-0.9.8-py2.7-macosx-10.10-intel.egg/sqlalchemy/pool.py", line 250, in _close_connection
    self._dialect.do_close(connection)
  File "/Library/Python/2.7/site-packages/SQLAlchemy-0.9.8-py2.7-macosx-10.10-intel.egg/sqlalchemy/engine/default.py", line 412, in do_close
    dbapi_connection.close()
ProgrammingError: SQLite objects created in a thread can only be used in that same thread.The object was created in thread id 4345303040 and this is thread id 140735173817088
2015-02-04 14:58:43,802 pool _finalize_fairy 574 : Exception during reset or similar
Traceback (most recent call last):
  File "/Library/Python/2.7/site-packages/SQLAlchemy-0.9.8-py2.7-macosx-10.10-intel.egg/sqlalchemy/pool.py", line 567, in _finalize_fairy
    fairy._reset(pool)
  File "/Library/Python/2.7/site-packages/SQLAlchemy-0.9.8-py2.7-macosx-10.10-intel.egg/sqlalchemy/pool.py", line 701, in _reset
    pool._dialect.do_rollback(self)
  File "/Library/Python/2.7/site-packages/SQLAlchemy-0.9.8-py2.7-macosx-10.10-intel.egg/sqlalchemy/engine/default.py", line 406, in do_rollback
    dbapi_connection.rollback()
ProgrammingError: SQLite objects created in a thread can only be used in that same thread.The object was created in thread id 4523560960 and this is thread id 140735173817088
2015-02-04 14:58:43,803 pool _close_connection 255 : Exception closing connection <sqlite3.Connection object at 0x10c785770>
Traceback (most recent call last):
  File "/Library/Python/2.7/site-packages/SQLAlchemy-0.9.8-py2.7-macosx-10.10-intel.egg/sqlalchemy/pool.py", line 250, in _close_connection
    self._dialect.do_close(connection)
  File "/Library/Python/2.7/site-packages/SQLAlchemy-0.9.8-py2.7-macosx-10.10-intel.egg/sqlalchemy/engine/default.py", line 412, in do_close
    dbapi_connection.close()
ProgrammingError: SQLite objects created in a thread can only be used in that same thread.The object was created in thread id 4523560960 and this is thread id 140735173817088
2015-02-04 15:45:22,032 pool _finalize_fairy 574 : Exception during reset or similar
Traceback (most recent call last):
  File "/Library/Python/2.7/site-packages/SQLAlchemy-0.9.8-py2.7-macosx-10.10-intel.egg/sqlalchemy/pool.py", line 567, in _finalize_fairy
    fairy._reset(pool)
  File "/Library/Python/2.7/site-packages/SQLAlchemy-0.9.8-py2.7-macosx-10.10-intel.egg/sqlalchemy/pool.py", line 701, in _reset
    pool._dialect.do_rollback(self)
  File "/Library/Python/2.7/site-packages/SQLAlchemy-0.9.8-py2.7-macosx-10.10-intel.egg/sqlalchemy/engine/default.py", line 406, in do_rollback
    dbapi_connection.rollback()
ProgrammingError: SQLite objects created in a thread can only be used in that same thread.The object was created in thread id 4513075200 and this is thread id 140735173817088
2015-02-04 15:45:22,034 pool _close_connection 255 : Exception closing connection <sqlite3.Connection object at 0x10be68770>
Traceback (most recent call last):
  File "/Library/Python/2.7/site-packages/SQLAlchemy-0.9.8-py2.7-macosx-10.10-intel.egg/sqlalchemy/pool.py", line 250, in _close_connection
    self._dialect.do_close(connection)
  File "/Library/Python/2.7/site-packages/SQLAlchemy-0.9.8-py2.7-macosx-10.10-intel.egg/sqlalchemy/engine/default.py", line 412, in do_close
    dbapi_connection.close()
ProgrammingError: SQLite objects created in a thread can only be used in that same thread.The object was created in thread id 4513075200 and this is thread id 140735173817088
2015-02-05 13:39:50,660 pool _finalize_fairy 574 : Exception during reset or similar
Traceback (most recent call last):
  File "/Library/Python/2.7/site-packages/SQLAlchemy-0.9.8-py2.7-macosx-10.10-intel.egg/sqlalchemy/pool.py", line 567, in _finalize_fairy
    fairy._reset(pool)
  File "/Library/Python/2.7/site-packages/SQLAlchemy-0.9.8-py2.7-macosx-10.10-intel.egg/sqlalchemy/pool.py", line 701, in _reset
    pool._dialect.do_rollback(self)
  File "/Library/Python/2.7/site-packages/SQLAlchemy-0.9.8-py2.7-macosx-10.10-intel.egg/sqlalchemy/engine/default.py", line 406, in do_rollback
    dbapi_connection.rollback()
ProgrammingError: SQLite objects created in a thread can only be used in that same thread.The object was created in thread id 4427091968 and this is thread id 140735173817088
2015-02-05 13:39:50,667 pool _close_connection 255 : Exception closing connection <sqlite3.Connection object at 0x106bb3770>
Traceback (most recent call last):
  File "/Library/Python/2.7/site-packages/SQLAlchemy-0.9.8-py2.7-macosx-10.10-intel.egg/sqlalchemy/pool.py", line 250, in _close_connection
    self._dialect.do_close(connection)
  File "/Library/Python/2.7/site-packages/SQLAlchemy-0.9.8-py2.7-macosx-10.10-intel.egg/sqlalchemy/engine/default.py", line 412, in do_close
    dbapi_connection.close()
ProgrammingError: SQLite objects created in a thread can only be used in that same thread.The object was created in thread id 4427091968 and this is thread id 140735173817088
2015-02-09 09:37:00,269 pool _finalize_fairy 574 : Exception during reset or similar
Traceback (most recent call last):
  File "/Library/Python/2.7/site-packages/SQLAlchemy-0.9.8-py2.7-macosx-10.10-intel.egg/sqlalchemy/pool.py", line 567, in _finalize_fairy
    fairy._reset(pool)
  File "/Library/Python/2.7/site-packages/SQLAlchemy-0.9.8-py2.7-macosx-10.10-intel.egg/sqlalchemy/pool.py", line 701, in _reset
    pool._dialect.do_rollback(self)
  File "/Library/Python/2.7/site-packages/SQLAlchemy-0.9.8-py2.7-macosx-10.10-intel.egg/sqlalchemy/engine/default.py", line 406, in do_rollback
    dbapi_connection.rollback()
ProgrammingError: SQLite objects created in a thread can only be used in that same thread.The object was created in thread id 4508880896 and this is thread id 140735173817088
2015-02-09 09:37:00,275 pool _close_connection 255 : Exception closing connection <sqlite3.Connection object at 0x10bae0770>
Traceback (most recent call last):
  File "/Library/Python/2.7/site-packages/SQLAlchemy-0.9.8-py2.7-macosx-10.10-intel.egg/sqlalchemy/pool.py", line 250, in _close_connection
    self._dialect.do_close(connection)
  File "/Library/Python/2.7/site-packages/SQLAlchemy-0.9.8-py2.7-macosx-10.10-intel.egg/sqlalchemy/engine/default.py", line 412, in do_close
    dbapi_connection.close()
ProgrammingError: SQLite objects created in a thread can only be used in that same thread.The object was created in thread id 4508880896 and this is thread id 140735173817088
2015-02-09 13:22:43,072 pool _finalize_fairy 574 : Exception during reset or similar
Traceback (most recent call last):
  File "/Library/Python/2.7/site-packages/SQLAlchemy-0.9.8-py2.7-macosx-10.10-intel.egg/sqlalchemy/pool.py", line 567, in _finalize_fairy
    fairy._reset(pool)
  File "/Library/Python/2.7/site-packages/SQLAlchemy-0.9.8-py2.7-macosx-10.10-intel.egg/sqlalchemy/pool.py", line 701, in _reset
    pool._dialect.do_rollback(self)
  File "/Library/Python/2.7/site-packages/SQLAlchemy-0.9.8-py2.7-macosx-10.10-intel.egg/sqlalchemy/engine/default.py", line 406, in do_rollback
    dbapi_connection.rollback()
ProgrammingError: SQLite objects created in a thread can only be used in that same thread.The object was created in thread id 4508880896 and this is thread id 140735173817088
2015-02-09 13:22:43,078 pool _close_connection 255 : Exception closing connection <sqlite3.Connection object at 0x10b9cf770>
Traceback (most recent call last):
  File "/Library/Python/2.7/site-packages/SQLAlchemy-0.9.8-py2.7-macosx-10.10-intel.egg/sqlalchemy/pool.py", line 250, in _close_connection
    self._dialect.do_close(connection)
  File "/Library/Python/2.7/site-packages/SQLAlchemy-0.9.8-py2.7-macosx-10.10-intel.egg/sqlalchemy/engine/default.py", line 412, in do_close
    dbapi_connection.close()
ProgrammingError: SQLite objects created in a thread can only be used in that same thread.The object was created in thread id 4508880896 and this is thread id 140735173817088
2015-02-12 09:39:20,625 pool _finalize_fairy 574 : Exception during reset or similar
Traceback (most recent call last):
  File "/Library/Python/2.7/site-packages/SQLAlchemy-0.9.8-py2.7-macosx-10.10-intel.egg/sqlalchemy/pool.py", line 567, in _finalize_fairy
    fairy._reset(pool)
  File "/Library/Python/2.7/site-packages/SQLAlchemy-0.9.8-py2.7-macosx-10.10-intel.egg/sqlalchemy/pool.py", line 701, in _reset
    pool._dialect.do_rollback(self)
  File "/Library/Python/2.7/site-packages/SQLAlchemy-0.9.8-py2.7-macosx-10.10-intel.egg/sqlalchemy/engine/default.py", line 406, in do_rollback
    dbapi_connection.rollback()
ProgrammingError: SQLite objects created in a thread can only be used in that same thread.The object was created in thread id 4492103680 and this is thread id 140735173817088
2015-02-12 09:39:20,628 pool _close_connection 255 : Exception closing connection <sqlite3.Connection object at 0x10aaae770>
Traceback (most recent call last):
  File "/Library/Python/2.7/site-packages/SQLAlchemy-0.9.8-py2.7-macosx-10.10-intel.egg/sqlalchemy/pool.py", line 250, in _close_connection
    self._dialect.do_close(connection)
  File "/Library/Python/2.7/site-packages/SQLAlchemy-0.9.8-py2.7-macosx-10.10-intel.egg/sqlalchemy/engine/default.py", line 412, in do_close
    dbapi_connection.close()
ProgrammingError: SQLite objects created in a thread can only be used in that same thread.The object was created in thread id 4492103680 and this is thread id 140735173817088
2015-02-12 09:41:50,379 pool _finalize_fairy 574 : Exception during reset or similar
Traceback (most recent call last):
  File "/Library/Python/2.7/site-packages/SQLAlchemy-0.9.8-py2.7-macosx-10.10-intel.egg/sqlalchemy/pool.py", line 567, in _finalize_fairy
    fairy._reset(pool)
  File "/Library/Python/2.7/site-packages/SQLAlchemy-0.9.8-py2.7-macosx-10.10-intel.egg/sqlalchemy/pool.py", line 701, in _reset
    pool._dialect.do_rollback(self)
  File "/Library/Python/2.7/site-packages/SQLAlchemy-0.9.8-py2.7-macosx-10.10-intel.egg/sqlalchemy/engine/default.py", line 406, in do_rollback
    dbapi_connection.rollback()
ProgrammingError: SQLite objects created in a thread can only be used in that same thread.The object was created in thread id 4444000256 and this is thread id 140735173817088
2015-02-12 09:41:50,383 pool _close_connection 255 : Exception closing connection <sqlite3.Connection object at 0x107d39770>
Traceback (most recent call last):
  File "/Library/Python/2.7/site-packages/SQLAlchemy-0.9.8-py2.7-macosx-10.10-intel.egg/sqlalchemy/pool.py", line 250, in _close_connection
    self._dialect.do_close(connection)
  File "/Library/Python/2.7/site-packages/SQLAlchemy-0.9.8-py2.7-macosx-10.10-intel.egg/sqlalchemy/engine/default.py", line 412, in do_close
    dbapi_connection.close()
ProgrammingError: SQLite objects created in a thread can only be used in that same thread.The object was created in thread id 4444000256 and this is thread id 140735173817088
2015-02-19 10:01:40,282 pool _finalize_fairy 574 : Exception during reset or similar
Traceback (most recent call last):
  File "/Library/Python/2.7/site-packages/SQLAlchemy-0.9.8-py2.7-macosx-10.10-intel.egg/sqlalchemy/pool.py", line 567, in _finalize_fairy
    fairy._reset(pool)
  File "/Library/Python/2.7/site-packages/SQLAlchemy-0.9.8-py2.7-macosx-10.10-intel.egg/sqlalchemy/pool.py", line 701, in _reset
    pool._dialect.do_rollback(self)
  File "/Library/Python/2.7/site-packages/SQLAlchemy-0.9.8-py2.7-macosx-10.10-intel.egg/sqlalchemy/engine/default.py", line 406, in do_rollback
    dbapi_connection.rollback()
ProgrammingError: SQLite objects created in a thread can only be used in that same thread.The object was created in thread id 4580184064 and this is thread id 140735117628160
2015-02-19 10:01:40,286 pool _close_connection 255 : Exception closing connection <sqlite3.Connection object at 0x10fdfd770>
Traceback (most recent call last):
  File "/Library/Python/2.7/site-packages/SQLAlchemy-0.9.8-py2.7-macosx-10.10-intel.egg/sqlalchemy/pool.py", line 250, in _close_connection
    self._dialect.do_close(connection)
  File "/Library/Python/2.7/site-packages/SQLAlchemy-0.9.8-py2.7-macosx-10.10-intel.egg/sqlalchemy/engine/default.py", line 412, in do_close
    dbapi_connection.close()
ProgrammingError: SQLite objects created in a thread can only be used in that same thread.The object was created in thread id 4580184064 and this is thread id 140735117628160
2015-02-19 10:05:58,944 pool _finalize_fairy 574 : Exception during reset or similar
Traceback (most recent call last):
  File "/Library/Python/2.7/site-packages/SQLAlchemy-0.9.8-py2.7-macosx-10.10-intel.egg/sqlalchemy/pool.py", line 567, in _finalize_fairy
    fairy._reset(pool)
  File "/Library/Python/2.7/site-packages/SQLAlchemy-0.9.8-py2.7-macosx-10.10-intel.egg/sqlalchemy/pool.py", line 701, in _reset
    pool._dialect.do_rollback(self)
  File "/Library/Python/2.7/site-packages/SQLAlchemy-0.9.8-py2.7-macosx-10.10-intel.egg/sqlalchemy/engine/default.py", line 406, in do_rollback
    dbapi_connection.rollback()
ProgrammingError: SQLite objects created in a thread can only be used in that same thread.The object was created in thread id 4588572672 and this is thread id 140735117628160
2015-02-19 10:05:58,946 pool _close_connection 255 : Exception closing connection <sqlite3.Connection object at 0x1106a0770>
Traceback (most recent call last):
  File "/Library/Python/2.7/site-packages/SQLAlchemy-0.9.8-py2.7-macosx-10.10-intel.egg/sqlalchemy/pool.py", line 250, in _close_connection
    self._dialect.do_close(connection)
  File "/Library/Python/2.7/site-packages/SQLAlchemy-0.9.8-py2.7-macosx-10.10-intel.egg/sqlalchemy/engine/default.py", line 412, in do_close
    dbapi_connection.close()
ProgrammingError: SQLite objects created in a thread can only be used in that same thread.The object was created in thread id 4588572672 and this is thread id 140735117628160
2015-02-19 15:52:36,304 pool _finalize_fairy 574 : Exception during reset or similar
Traceback (most recent call last):
  File "/Library/Python/2.7/site-packages/SQLAlchemy-0.9.8-py2.7-macosx-10.10-intel.egg/sqlalchemy/pool.py", line 567, in _finalize_fairy
    fairy._reset(pool)
  File "/Library/Python/2.7/site-packages/SQLAlchemy-0.9.8-py2.7-macosx-10.10-intel.egg/sqlalchemy/pool.py", line 701, in _reset
    pool._dialect.do_rollback(self)
  File "/Library/Python/2.7/site-packages/SQLAlchemy-0.9.8-py2.7-macosx-10.10-intel.egg/sqlalchemy/engine/default.py", line 406, in do_rollback
    dbapi_connection.rollback()
ProgrammingError: SQLite objects created in a thread can only be used in that same thread.The object was created in thread id 4559212544 and this is thread id 140735117628160
2015-02-19 15:52:36,308 pool _close_connection 255 : Exception closing connection <sqlite3.Connection object at 0x10eb28770>
Traceback (most recent call last):
  File "/Library/Python/2.7/site-packages/SQLAlchemy-0.9.8-py2.7-macosx-10.10-intel.egg/sqlalchemy/pool.py", line 250, in _close_connection
    self._dialect.do_close(connection)
  File "/Library/Python/2.7/site-packages/SQLAlchemy-0.9.8-py2.7-macosx-10.10-intel.egg/sqlalchemy/engine/default.py", line 412, in do_close
    dbapi_connection.close()
ProgrammingError: SQLite objects created in a thread can only be used in that same thread.The object was created in thread id 4559212544 and this is thread id 140735117628160
2015-02-20 14:08:50,315 pool _finalize_fairy 574 : Exception during reset or similar
Traceback (most recent call last):
  File "/Library/Python/2.7/site-packages/SQLAlchemy-0.9.8-py2.7-macosx-10.10-intel.egg/sqlalchemy/pool.py", line 567, in _finalize_fairy
    fairy._reset(pool)
  File "/Library/Python/2.7/site-packages/SQLAlchemy-0.9.8-py2.7-macosx-10.10-intel.egg/sqlalchemy/pool.py", line 701, in _reset
    pool._dialect.do_rollback(self)
  File "/Library/Python/2.7/site-packages/SQLAlchemy-0.9.8-py2.7-macosx-10.10-intel.egg/sqlalchemy/engine/default.py", line 406, in do_rollback
    dbapi_connection.rollback()
ProgrammingError: SQLite objects created in a thread can only be used in that same thread.The object was created in thread id 4414509056 and this is thread id 140735117628160
2015-02-20 14:08:50,319 pool _close_connection 255 : Exception closing connection <sqlite3.Connection object at 0x106091770>
Traceback (most recent call last):
  File "/Library/Python/2.7/site-packages/SQLAlchemy-0.9.8-py2.7-macosx-10.10-intel.egg/sqlalchemy/pool.py", line 250, in _close_connection
    self._dialect.do_close(connection)
  File "/Library/Python/2.7/site-packages/SQLAlchemy-0.9.8-py2.7-macosx-10.10-intel.egg/sqlalchemy/engine/default.py", line 412, in do_close
    dbapi_connection.close()
ProgrammingError: SQLite objects created in a thread can only be used in that same thread.The object was created in thread id 4414509056 and this is thread id 140735117628160
2015-02-23 09:31:13,255 pool _finalize_fairy 574 : Exception during reset or similar
Traceback (most recent call last):
  File "/Library/Python/2.7/site-packages/SQLAlchemy-0.9.8-py2.7-macosx-10.10-intel.egg/sqlalchemy/pool.py", line 567, in _finalize_fairy
    fairy._reset(pool)
  File "/Library/Python/2.7/site-packages/SQLAlchemy-0.9.8-py2.7-macosx-10.10-intel.egg/sqlalchemy/pool.py", line 701, in _reset
    pool._dialect.do_rollback(self)
  File "/Library/Python/2.7/site-packages/SQLAlchemy-0.9.8-py2.7-macosx-10.10-intel.egg/sqlalchemy/engine/default.py", line 406, in do_rollback
    dbapi_connection.rollback()
ProgrammingError: SQLite objects created in a thread can only be used in that same thread.The object was created in thread id 4469035008 and this is thread id 140735117628160
2015-02-23 09:31:13,258 pool _close_connection 255 : Exception closing connection <sqlite3.Connection object at 0x10951e770>
Traceback (most recent call last):
  File "/Library/Python/2.7/site-packages/SQLAlchemy-0.9.8-py2.7-macosx-10.10-intel.egg/sqlalchemy/pool.py", line 250, in _close_connection
    self._dialect.do_close(connection)
  File "/Library/Python/2.7/site-packages/SQLAlchemy-0.9.8-py2.7-macosx-10.10-intel.egg/sqlalchemy/engine/default.py", line 412, in do_close
    dbapi_connection.close()
ProgrammingError: SQLite objects created in a thread can only be used in that same thread.The object was created in thread id 4469035008 and this is thread id 140735117628160
2015-02-23 10:12:26,742 pool _finalize_fairy 574 : Exception during reset or similar
Traceback (most recent call last):
  File "/Library/Python/2.7/site-packages/SQLAlchemy-0.9.8-py2.7-macosx-10.10-intel.egg/sqlalchemy/pool.py", line 567, in _finalize_fairy
    fairy._reset(pool)
  File "/Library/Python/2.7/site-packages/SQLAlchemy-0.9.8-py2.7-macosx-10.10-intel.egg/sqlalchemy/pool.py", line 701, in _reset
    pool._dialect.do_rollback(self)
  File "/Library/Python/2.7/site-packages/SQLAlchemy-0.9.8-py2.7-macosx-10.10-intel.egg/sqlalchemy/engine/default.py", line 406, in do_rollback
    dbapi_connection.rollback()
ProgrammingError: SQLite objects created in a thread can only be used in that same thread.The object was created in thread id 4416606208 and this is thread id 140735117628160
2015-02-23 10:12:26,746 pool _close_connection 255 : Exception closing connection <sqlite3.Connection object at 0x1062b7770>
Traceback (most recent call last):
  File "/Library/Python/2.7/site-packages/SQLAlchemy-0.9.8-py2.7-macosx-10.10-intel.egg/sqlalchemy/pool.py", line 250, in _close_connection
    self._dialect.do_close(connection)
  File "/Library/Python/2.7/site-packages/SQLAlchemy-0.9.8-py2.7-macosx-10.10-intel.egg/sqlalchemy/engine/default.py", line 412, in do_close
    dbapi_connection.close()
ProgrammingError: SQLite objects created in a thread can only be used in that same thread.The object was created in thread id 4416606208 and this is thread id 140735117628160
2015-02-23 10:24:53,714 pool _finalize_fairy 574 : Exception during reset or similar
Traceback (most recent call last):
  File "/Library/Python/2.7/site-packages/SQLAlchemy-0.9.8-py2.7-macosx-10.10-intel.egg/sqlalchemy/pool.py", line 567, in _finalize_fairy
    fairy._reset(pool)
  File "/Library/Python/2.7/site-packages/SQLAlchemy-0.9.8-py2.7-macosx-10.10-intel.egg/sqlalchemy/pool.py", line 701, in _reset
    pool._dialect.do_rollback(self)
  File "/Library/Python/2.7/site-packages/SQLAlchemy-0.9.8-py2.7-macosx-10.10-intel.egg/sqlalchemy/engine/default.py", line 406, in do_rollback
    dbapi_connection.rollback()
ProgrammingError: SQLite objects created in a thread can only be used in that same thread.The object was created in thread id 4408217600 and this is thread id 140735117628160
2015-02-23 10:24:53,717 pool _close_connection 255 : Exception closing connection <sqlite3.Connection object at 0x105a22770>
Traceback (most recent call last):
  File "/Library/Python/2.7/site-packages/SQLAlchemy-0.9.8-py2.7-macosx-10.10-intel.egg/sqlalchemy/pool.py", line 250, in _close_connection
    self._dialect.do_close(connection)
  File "/Library/Python/2.7/site-packages/SQLAlchemy-0.9.8-py2.7-macosx-10.10-intel.egg/sqlalchemy/engine/default.py", line 412, in do_close
    dbapi_connection.close()
ProgrammingError: SQLite objects created in a thread can only be used in that same thread.The object was created in thread id 4408217600 and this is thread id 140735117628160
2015-02-23 14:54:14,716 pool _finalize_fairy 574 : Exception during reset or similar
Traceback (most recent call last):
  File "/Library/Python/2.7/site-packages/SQLAlchemy-0.9.8-py2.7-macosx-10.10-intel.egg/sqlalchemy/pool.py", line 567, in _finalize_fairy
    fairy._reset(pool)
  File "/Library/Python/2.7/site-packages/SQLAlchemy-0.9.8-py2.7-macosx-10.10-intel.egg/sqlalchemy/pool.py", line 701, in _reset
    pool._dialect.do_rollback(self)
  File "/Library/Python/2.7/site-packages/SQLAlchemy-0.9.8-py2.7-macosx-10.10-intel.egg/sqlalchemy/engine/default.py", line 406, in do_rollback
    dbapi_connection.rollback()
ProgrammingError: SQLite objects created in a thread can only be used in that same thread.The object was created in thread id 4397731840 and this is thread id 140735117628160
2015-02-23 14:54:14,721 pool _close_connection 255 : Exception closing connection <sqlite3.Connection object at 0x105070770>
Traceback (most recent call last):
  File "/Library/Python/2.7/site-packages/SQLAlchemy-0.9.8-py2.7-macosx-10.10-intel.egg/sqlalchemy/pool.py", line 250, in _close_connection
    self._dialect.do_close(connection)
  File "/Library/Python/2.7/site-packages/SQLAlchemy-0.9.8-py2.7-macosx-10.10-intel.egg/sqlalchemy/engine/default.py", line 412, in do_close
    dbapi_connection.close()
ProgrammingError: SQLite objects created in a thread can only be used in that same thread.The object was created in thread id 4397731840 and this is thread id 140735117628160
2015-02-23 15:25:54,454 pool _finalize_fairy 574 : Exception during reset or similar
Traceback (most recent call last):
  File "/Library/Python/2.7/site-packages/SQLAlchemy-0.9.8-py2.7-macosx-10.10-intel.egg/sqlalchemy/pool.py", line 567, in _finalize_fairy
    fairy._reset(pool)
  File "/Library/Python/2.7/site-packages/SQLAlchemy-0.9.8-py2.7-macosx-10.10-intel.egg/sqlalchemy/pool.py", line 701, in _reset
    pool._dialect.do_rollback(self)
  File "/Library/Python/2.7/site-packages/SQLAlchemy-0.9.8-py2.7-macosx-10.10-intel.egg/sqlalchemy/engine/default.py", line 406, in do_rollback
    dbapi_connection.rollback()
ProgrammingError: SQLite objects created in a thread can only be used in that same thread.The object was created in thread id 4370468864 and this is thread id 140735082386176
2015-02-23 15:25:54,457 pool _close_connection 255 : Exception closing connection <sqlite3.Connection object at 0x103685770>
Traceback (most recent call last):
  File "/Library/Python/2.7/site-packages/SQLAlchemy-0.9.8-py2.7-macosx-10.10-intel.egg/sqlalchemy/pool.py", line 250, in _close_connection
    self._dialect.do_close(connection)
  File "/Library/Python/2.7/site-packages/SQLAlchemy-0.9.8-py2.7-macosx-10.10-intel.egg/sqlalchemy/engine/default.py", line 412, in do_close
    dbapi_connection.close()
ProgrammingError: SQLite objects created in a thread can only be used in that same thread.The object was created in thread id 4370468864 and this is thread id 140735082386176
2015-02-23 15:33:08,993 pool _finalize_fairy 574 : Exception during reset or similar
Traceback (most recent call last):
  File "/Library/Python/2.7/site-packages/SQLAlchemy-0.9.8-py2.7-macosx-10.10-intel.egg/sqlalchemy/pool.py", line 567, in _finalize_fairy
    fairy._reset(pool)
  File "/Library/Python/2.7/site-packages/SQLAlchemy-0.9.8-py2.7-macosx-10.10-intel.egg/sqlalchemy/pool.py", line 701, in _reset
    pool._dialect.do_rollback(self)
  File "/Library/Python/2.7/site-packages/SQLAlchemy-0.9.8-py2.7-macosx-10.10-intel.egg/sqlalchemy/engine/default.py", line 406, in do_rollback
    dbapi_connection.rollback()
ProgrammingError: SQLite objects created in a thread can only be used in that same thread.The object was created in thread id 4534046720 and this is thread id 140735082386176
2015-02-23 15:33:08,998 pool _close_connection 255 : Exception closing connection <sqlite3.Connection object at 0x10d149770>
Traceback (most recent call last):
  File "/Library/Python/2.7/site-packages/SQLAlchemy-0.9.8-py2.7-macosx-10.10-intel.egg/sqlalchemy/pool.py", line 250, in _close_connection
    self._dialect.do_close(connection)
  File "/Library/Python/2.7/site-packages/SQLAlchemy-0.9.8-py2.7-macosx-10.10-intel.egg/sqlalchemy/engine/default.py", line 412, in do_close
    dbapi_connection.close()
ProgrammingError: SQLite objects created in a thread can only be used in that same thread.The object was created in thread id 4534046720 and this is thread id 140735082386176
2015-02-24 14:09:18,948 pool _finalize_fairy 574 : Exception during reset or similar
Traceback (most recent call last):
  File "/Library/Python/2.7/site-packages/SQLAlchemy-0.9.8-py2.7-macosx-10.10-intel.egg/sqlalchemy/pool.py", line 567, in _finalize_fairy
    fairy._reset(pool)
  File "/Library/Python/2.7/site-packages/SQLAlchemy-0.9.8-py2.7-macosx-10.10-intel.egg/sqlalchemy/pool.py", line 701, in _reset
    pool._dialect.do_rollback(self)
  File "/Library/Python/2.7/site-packages/SQLAlchemy-0.9.8-py2.7-macosx-10.10-intel.egg/sqlalchemy/engine/default.py", line 406, in do_rollback
    dbapi_connection.rollback()
ProgrammingError: SQLite objects created in a thread can only be used in that same thread.The object was created in thread id 4460646400 and this is thread id 140735082386176
2015-02-24 14:09:18,956 pool _close_connection 255 : Exception closing connection <sqlite3.Connection object at 0x108b82770>
Traceback (most recent call last):
  File "/Library/Python/2.7/site-packages/SQLAlchemy-0.9.8-py2.7-macosx-10.10-intel.egg/sqlalchemy/pool.py", line 250, in _close_connection
    self._dialect.do_close(connection)
  File "/Library/Python/2.7/site-packages/SQLAlchemy-0.9.8-py2.7-macosx-10.10-intel.egg/sqlalchemy/engine/default.py", line 412, in do_close
    dbapi_connection.close()
ProgrammingError: SQLite objects created in a thread can only be used in that same thread.The object was created in thread id 4460646400 and this is thread id 140735082386176
2015-02-24 16:13:10,302 pool _finalize_fairy 574 : Exception during reset or similar
Traceback (most recent call last):
  File "/Library/Python/2.7/site-packages/SQLAlchemy-0.9.8-py2.7-macosx-10.10-intel.egg/sqlalchemy/pool.py", line 567, in _finalize_fairy
    fairy._reset(pool)
  File "/Library/Python/2.7/site-packages/SQLAlchemy-0.9.8-py2.7-macosx-10.10-intel.egg/sqlalchemy/pool.py", line 701, in _reset
    pool._dialect.do_rollback(self)
  File "/Library/Python/2.7/site-packages/SQLAlchemy-0.9.8-py2.7-macosx-10.10-intel.egg/sqlalchemy/engine/default.py", line 406, in do_rollback
    dbapi_connection.rollback()
ProgrammingError: SQLite objects created in a thread can only be used in that same thread.The object was created in thread id 4500492288 and this is thread id 140735082386176
2015-02-24 16:13:10,306 pool _close_connection 255 : Exception closing connection <sqlite3.Connection object at 0x10b178770>
Traceback (most recent call last):
  File "/Library/Python/2.7/site-packages/SQLAlchemy-0.9.8-py2.7-macosx-10.10-intel.egg/sqlalchemy/pool.py", line 250, in _close_connection
    self._dialect.do_close(connection)
  File "/Library/Python/2.7/site-packages/SQLAlchemy-0.9.8-py2.7-macosx-10.10-intel.egg/sqlalchemy/engine/default.py", line 412, in do_close
    dbapi_connection.close()
ProgrammingError: SQLite objects created in a thread can only be used in that same thread.The object was created in thread id 4500492288 and this is thread id 140735082386176
2015-02-26 09:14:10,636 pool _finalize_fairy 574 : Exception during reset or similar
Traceback (most recent call last):
  File "/Library/Python/2.7/site-packages/SQLAlchemy-0.9.8-py2.7-macosx-10.10-intel.egg/sqlalchemy/pool.py", line 567, in _finalize_fairy
    fairy._reset(pool)
  File "/Library/Python/2.7/site-packages/SQLAlchemy-0.9.8-py2.7-macosx-10.10-intel.egg/sqlalchemy/pool.py", line 701, in _reset
    pool._dialect.do_rollback(self)
  File "/Library/Python/2.7/site-packages/SQLAlchemy-0.9.8-py2.7-macosx-10.10-intel.egg/sqlalchemy/engine/default.py", line 406, in do_rollback
    dbapi_connection.rollback()
ProgrammingError: SQLite objects created in a thread can only be used in that same thread.The object was created in thread id 4575989760 and this is thread id 140735082386176
2015-02-26 09:14:10,640 pool _close_connection 255 : Exception closing connection <sqlite3.Connection object at 0x10fb28770>
Traceback (most recent call last):
  File "/Library/Python/2.7/site-packages/SQLAlchemy-0.9.8-py2.7-macosx-10.10-intel.egg/sqlalchemy/pool.py", line 250, in _close_connection
    self._dialect.do_close(connection)
  File "/Library/Python/2.7/site-packages/SQLAlchemy-0.9.8-py2.7-macosx-10.10-intel.egg/sqlalchemy/engine/default.py", line 412, in do_close
    dbapi_connection.close()
ProgrammingError: SQLite objects created in a thread can only be used in that same thread.The object was created in thread id 4575989760 and this is thread id 140735082386176
2015-02-27 14:16:38,323 pool _finalize_fairy 574 : Exception during reset or similar
Traceback (most recent call last):
  File "/Library/Python/2.7/site-packages/SQLAlchemy-0.9.8-py2.7-macosx-10.10-intel.egg/sqlalchemy/pool.py", line 567, in _finalize_fairy
    fairy._reset(pool)
  File "/Library/Python/2.7/site-packages/SQLAlchemy-0.9.8-py2.7-macosx-10.10-intel.egg/sqlalchemy/pool.py", line 701, in _reset
    pool._dialect.do_rollback(self)
  File "/Library/Python/2.7/site-packages/SQLAlchemy-0.9.8-py2.7-macosx-10.10-intel.egg/sqlalchemy/engine/default.py", line 406, in do_rollback
    dbapi_connection.rollback()
ProgrammingError: SQLite objects created in a thread can only be used in that same thread.The object was created in thread id 4473229312 and this is thread id 140735082386176
2015-02-27 14:16:38,326 pool _close_connection 255 : Exception closing connection <sqlite3.Connection object at 0x109852770>
Traceback (most recent call last):
  File "/Library/Python/2.7/site-packages/SQLAlchemy-0.9.8-py2.7-macosx-10.10-intel.egg/sqlalchemy/pool.py", line 250, in _close_connection
    self._dialect.do_close(connection)
  File "/Library/Python/2.7/site-packages/SQLAlchemy-0.9.8-py2.7-macosx-10.10-intel.egg/sqlalchemy/engine/default.py", line 412, in do_close
    dbapi_connection.close()
ProgrammingError: SQLite objects created in a thread can only be used in that same thread.The object was created in thread id 4473229312 and this is thread id 140735082386176
2015-03-02 09:15:48,727 pool _finalize_fairy 574 : Exception during reset or similar
Traceback (most recent call last):
  File "/Library/Python/2.7/site-packages/SQLAlchemy-0.9.8-py2.7-macosx-10.10-intel.egg/sqlalchemy/pool.py", line 567, in _finalize_fairy
    fairy._reset(pool)
  File "/Library/Python/2.7/site-packages/SQLAlchemy-0.9.8-py2.7-macosx-10.10-intel.egg/sqlalchemy/pool.py", line 701, in _reset
    pool._dialect.do_rollback(self)
  File "/Library/Python/2.7/site-packages/SQLAlchemy-0.9.8-py2.7-macosx-10.10-intel.egg/sqlalchemy/engine/default.py", line 406, in do_rollback
    dbapi_connection.rollback()
ProgrammingError: SQLite objects created in a thread can only be used in that same thread.The object was created in thread id 4341108736 and this is thread id 140735082386176
2015-03-02 09:15:48,730 pool _close_connection 255 : Exception closing connection <sqlite3.Connection object at 0x101949770>
Traceback (most recent call last):
  File "/Library/Python/2.7/site-packages/SQLAlchemy-0.9.8-py2.7-macosx-10.10-intel.egg/sqlalchemy/pool.py", line 250, in _close_connection
    self._dialect.do_close(connection)
  File "/Library/Python/2.7/site-packages/SQLAlchemy-0.9.8-py2.7-macosx-10.10-intel.egg/sqlalchemy/engine/default.py", line 412, in do_close
    dbapi_connection.close()
ProgrammingError: SQLite objects created in a thread can only be used in that same thread.The object was created in thread id 4341108736 and this is thread id 140735082386176
2015-03-02 14:50:30,740 pool _finalize_fairy 574 : Exception during reset or similar
Traceback (most recent call last):
  File "/Library/Python/2.7/site-packages/SQLAlchemy-0.9.8-py2.7-macosx-10.10-intel.egg/sqlalchemy/pool.py", line 567, in _finalize_fairy
    fairy._reset(pool)
  File "/Library/Python/2.7/site-packages/SQLAlchemy-0.9.8-py2.7-macosx-10.10-intel.egg/sqlalchemy/pool.py", line 701, in _reset
    pool._dialect.do_rollback(self)
  File "/Library/Python/2.7/site-packages/SQLAlchemy-0.9.8-py2.7-macosx-10.10-intel.egg/sqlalchemy/engine/default.py", line 406, in do_rollback
    dbapi_connection.rollback()
ProgrammingError: SQLite objects created in a thread can only be used in that same thread.The object was created in thread id 4368371712 and this is thread id 140735082386176
2015-03-02 14:50:30,745 pool _close_connection 255 : Exception closing connection <sqlite3.Connection object at 0x10341a770>
Traceback (most recent call last):
  File "/Library/Python/2.7/site-packages/SQLAlchemy-0.9.8-py2.7-macosx-10.10-intel.egg/sqlalchemy/pool.py", line 250, in _close_connection
    self._dialect.do_close(connection)
  File "/Library/Python/2.7/site-packages/SQLAlchemy-0.9.8-py2.7-macosx-10.10-intel.egg/sqlalchemy/engine/default.py", line 412, in do_close
    dbapi_connection.close()
ProgrammingError: SQLite objects created in a thread can only be used in that same thread.The object was created in thread id 4368371712 and this is thread id 140735082386176
2015-03-03 12:47:04,552 pool _finalize_fairy 574 : Exception during reset or similar
Traceback (most recent call last):
  File "/Library/Python/2.7/site-packages/SQLAlchemy-0.9.8-py2.7-macosx-10.10-intel.egg/sqlalchemy/pool.py", line 567, in _finalize_fairy
    fairy._reset(pool)
  File "/Library/Python/2.7/site-packages/SQLAlchemy-0.9.8-py2.7-macosx-10.10-intel.egg/sqlalchemy/pool.py", line 701, in _reset
    pool._dialect.do_rollback(self)
  File "/Library/Python/2.7/site-packages/SQLAlchemy-0.9.8-py2.7-macosx-10.10-intel.egg/sqlalchemy/engine/default.py", line 406, in do_rollback
    dbapi_connection.rollback()
ProgrammingError: SQLite objects created in a thread can only be used in that same thread.The object was created in thread id 4592766976 and this is thread id 140735082386176
2015-03-03 12:47:04,558 pool _close_connection 255 : Exception closing connection <sqlite3.Connection object at 0x110a99770>
Traceback (most recent call last):
  File "/Library/Python/2.7/site-packages/SQLAlchemy-0.9.8-py2.7-macosx-10.10-intel.egg/sqlalchemy/pool.py", line 250, in _close_connection
    self._dialect.do_close(connection)
  File "/Library/Python/2.7/site-packages/SQLAlchemy-0.9.8-py2.7-macosx-10.10-intel.egg/sqlalchemy/engine/default.py", line 412, in do_close
    dbapi_connection.close()
ProgrammingError: SQLite objects created in a thread can only be used in that same thread.The object was created in thread id 4592766976 and this is thread id 140735082386176
2015-03-03 13:36:48,607 pool _finalize_fairy 574 : Exception during reset or similar
Traceback (most recent call last):
  File "/Library/Python/2.7/site-packages/SQLAlchemy-0.9.8-py2.7-macosx-10.10-intel.egg/sqlalchemy/pool.py", line 567, in _finalize_fairy
    fairy._reset(pool)
  File "/Library/Python/2.7/site-packages/SQLAlchemy-0.9.8-py2.7-macosx-10.10-intel.egg/sqlalchemy/pool.py", line 701, in _reset
    pool._dialect.do_rollback(self)
  File "/Library/Python/2.7/site-packages/SQLAlchemy-0.9.8-py2.7-macosx-10.10-intel.egg/sqlalchemy/engine/default.py", line 406, in do_rollback
    dbapi_connection.rollback()
ProgrammingError: SQLite objects created in a thread can only be used in that same thread.The object was created in thread id 4458549248 and this is thread id 140735082386176
2015-03-03 13:36:48,630 pool _close_connection 255 : Exception closing connection <sqlite3.Connection object at 0x108abd770>
Traceback (most recent call last):
  File "/Library/Python/2.7/site-packages/SQLAlchemy-0.9.8-py2.7-macosx-10.10-intel.egg/sqlalchemy/pool.py", line 250, in _close_connection
    self._dialect.do_close(connection)
  File "/Library/Python/2.7/site-packages/SQLAlchemy-0.9.8-py2.7-macosx-10.10-intel.egg/sqlalchemy/engine/default.py", line 412, in do_close
    dbapi_connection.close()
ProgrammingError: SQLite objects created in a thread can only be used in that same thread.The object was created in thread id 4458549248 and this is thread id 140735082386176
2015-03-04 16:17:21,456 pool _finalize_fairy 574 : Exception during reset or similar
Traceback (most recent call last):
  File "/Library/Python/2.7/site-packages/SQLAlchemy-0.9.8-py2.7-macosx-10.10-intel.egg/sqlalchemy/pool.py", line 567, in _finalize_fairy
    fairy._reset(pool)
  File "/Library/Python/2.7/site-packages/SQLAlchemy-0.9.8-py2.7-macosx-10.10-intel.egg/sqlalchemy/pool.py", line 701, in _reset
    pool._dialect.do_rollback(self)
  File "/Library/Python/2.7/site-packages/SQLAlchemy-0.9.8-py2.7-macosx-10.10-intel.egg/sqlalchemy/engine/default.py", line 406, in do_rollback
    dbapi_connection.rollback()
ProgrammingError: SQLite objects created in a thread can only be used in that same thread.The object was created in thread id 4339011584 and this is thread id 140735082386176
2015-03-04 16:17:21,459 pool _close_connection 255 : Exception closing connection <sqlite3.Connection object at 0x10174b770>
Traceback (most recent call last):
  File "/Library/Python/2.7/site-packages/SQLAlchemy-0.9.8-py2.7-macosx-10.10-intel.egg/sqlalchemy/pool.py", line 250, in _close_connection
    self._dialect.do_close(connection)
  File "/Library/Python/2.7/site-packages/SQLAlchemy-0.9.8-py2.7-macosx-10.10-intel.egg/sqlalchemy/engine/default.py", line 412, in do_close
    dbapi_connection.close()
ProgrammingError: SQLite objects created in a thread can only be used in that same thread.The object was created in thread id 4339011584 and this is thread id 140735082386176
2015-03-04 16:22:58,482 pool _finalize_fairy 574 : Exception during reset or similar
Traceback (most recent call last):
  File "/Library/Python/2.7/site-packages/SQLAlchemy-0.9.8-py2.7-macosx-10.10-intel.egg/sqlalchemy/pool.py", line 567, in _finalize_fairy
    fairy._reset(pool)
  File "/Library/Python/2.7/site-packages/SQLAlchemy-0.9.8-py2.7-macosx-10.10-intel.egg/sqlalchemy/pool.py", line 701, in _reset
    pool._dialect.do_rollback(self)
  File "/Library/Python/2.7/site-packages/SQLAlchemy-0.9.8-py2.7-macosx-10.10-intel.egg/sqlalchemy/engine/default.py", line 406, in do_rollback
    dbapi_connection.rollback()
ProgrammingError: SQLite objects created in a thread can only be used in that same thread.The object was created in thread id 4466937856 and this is thread id 140735082386176
2015-03-04 16:22:58,485 pool _close_connection 255 : Exception closing connection <sqlite3.Connection object at 0x1091d3770>
Traceback (most recent call last):
  File "/Library/Python/2.7/site-packages/SQLAlchemy-0.9.8-py2.7-macosx-10.10-intel.egg/sqlalchemy/pool.py", line 250, in _close_connection
    self._dialect.do_close(connection)
  File "/Library/Python/2.7/site-packages/SQLAlchemy-0.9.8-py2.7-macosx-10.10-intel.egg/sqlalchemy/engine/default.py", line 412, in do_close
    dbapi_connection.close()
ProgrammingError: SQLite objects created in a thread can only be used in that same thread.The object was created in thread id 4466937856 and this is thread id 140735082386176
2015-03-05 10:54:12,255 pool _finalize_fairy 574 : Exception during reset or similar
Traceback (most recent call last):
  File "/Library/Python/2.7/site-packages/SQLAlchemy-0.9.8-py2.7-macosx-10.10-intel.egg/sqlalchemy/pool.py", line 567, in _finalize_fairy
    fairy._reset(pool)
  File "/Library/Python/2.7/site-packages/SQLAlchemy-0.9.8-py2.7-macosx-10.10-intel.egg/sqlalchemy/pool.py", line 701, in _reset
    pool._dialect.do_rollback(self)
  File "/Library/Python/2.7/site-packages/SQLAlchemy-0.9.8-py2.7-macosx-10.10-intel.egg/sqlalchemy/engine/default.py", line 406, in do_rollback
    dbapi_connection.rollback()
ProgrammingError: SQLite objects created in a thread can only be used in that same thread.The object was created in thread id 4527755264 and this is thread id 140735082386176
2015-03-05 10:54:12,258 pool _close_connection 255 : Exception closing connection <sqlite3.Connection object at 0x10ccdc770>
Traceback (most recent call last):
  File "/Library/Python/2.7/site-packages/SQLAlchemy-0.9.8-py2.7-macosx-10.10-intel.egg/sqlalchemy/pool.py", line 250, in _close_connection
    self._dialect.do_close(connection)
  File "/Library/Python/2.7/site-packages/SQLAlchemy-0.9.8-py2.7-macosx-10.10-intel.egg/sqlalchemy/engine/default.py", line 412, in do_close
    dbapi_connection.close()
ProgrammingError: SQLite objects created in a thread can only be used in that same thread.The object was created in thread id 4527755264 and this is thread id 140735082386176
